Workbook
Name Proteina: 'Base dados dieta'!$A$2:$F$198
Name Suplementação: #REF!

Sheet Base
C1: Nome: | G1: Suplementos Recomendados:
C2: Próxima atualização: | G2: Ver folha de suplementos
C3: Fim do Pack:
A5: DADOS PESSOAIS | D5: HOMEM | K5: METAS DIÁRIAS | O5: Calculo Macros
A6: Peso | D6: Taxa Metabólica Basal | E6: Peso(kg) | F6: Altura(cm) | G6: Idade | H6: Nivel Actividade Fisica | I6: Ajuste | K6: Kcal | L6: =D7+I7 -> 0 | O6: Kcal diárias
A7: Altura | D7: =(10*B6+6.25*B7-5*B8+5)*B9 -> 0 | E7: =B6 -> 0 | F7: =B7 -> 0 | G7: =B8 -> 0 | H7: =B9 -> 0 | K7: Proteina | L7: =(L21*B6) -> 0 | M7: =(L22*B6) -> 0 | P7: Proteina | Q7: Gordura | R7: Hidratos
A8: Idade | K8: Gordura | L8: =(K21*B6) -> 0 | M8: =(K22*B6) -> 0 | O8: Objectivo (g/kg) | P8: 2.3 | Q8: 0.8 | R8: 5
A9: Tipo actividade fisica | K9: Hidratos | L9: =(L6-((M7*4)+(M8*9)))/4 -> 0 | M9: =(L6-((L7*4)+(L8*9)))/4 -> 0 | O9: Total (gramas) | P9: =P8*E7 -> 0 | Q9: =Q8*E7 -> 0 | R9: =R8*E7 -> 0 | T9: =(P9*4)+(Q9*9)+(R9*4) -> 0
O10: Total (% Kcal) | P10: =(P9*4)/T9*100 -> #DIV/0! | Q10: =(Q9*9)/T9*100 -> #DIV/0! | R10: =(R9*4)/T9*100 -> #DIV/0!
A11: OBJETIVO | D11: MULHER | K11: METAS DIÁRIAS
A12: Ganhar massa muscular e melhorar mobilidade | D12: Taxa Metabólica Basal | E12: Peso(kg) | F12: Altura(cm) | G12: Idade | H12: Nivel Actividade Fisica | I12: Ajuste | K12: Kcal | L12: =D13+I13 -> 0 | O12: Objectivo (%) | P12: 25 | Q12: 20 | R12: 55
D13: =(10*B6+6.25*B7-5*B8-161)*B9 -> 0 | E13: =B6 -> 0 | F13: =B7 -> 0 | G13: =B8 -> 0 | H13: =B9 -> 0 | K13: Proteina | L13: =(L21*B6) -> 0 | M13: =(L22*B6) -> 0 | O13: Total (gramas) | P13: =(Q6*(P12/100)/4) -> 0 | Q13: =(Q6*(Q12/100)/9) -> 0 | R13: =(Q6*(R12/100)/4) -> 0 | T13: =(P13*4)+(Q13*9)+(R13*4) -> 0
A14: Limitações | K14: Gordura | L14: =(K21*B6) -> 0 | M14: =(K22*B6) -> 0 | O14: Total (g/kg) | P14: =P13/E7 -> #DIV/0! | Q14: =Q13/E7 -> #DIV/0! | R14: =R13/E7 -> #DIV/0!
A15: Trombo na perna que apanhou os dois pulmões | K15: Hidratos | L15: =(L12-((M13*4)+(M14*9)))/4 -> 0 | M15: =(L12-((L13*4)+(L14*9)))/4 -> 0
A16: Artrite | O16: Macros a utilizar
D17: Nivel Actividade Fisica
D18: 1. Sedentários = 1.2 (pouco ou nenhum exercício)
A19: Observações | D19: 2. Levemente ativo = 1.375 (exercício leve 1 a 3 dias por semana) | K19: Consumos
A20: Treino | D20: 3. Moderadamente ativo = 1.55 (exercício moderado, faz desporto 3 a 5 dias por semana) | K20: Gordura | L20: Proteina
A21: Frequência semanal | D21: 4. Altamente ativo = 1.725 (exercício pesado de 5 a 6 dias por semana) | K21: 0.5 | L21: 1.6
A22: Duração treino | D22: 5. Extremamente ativo = 1.9 (exercício pesado diariamente e até 2 vezes por dia) | K22: 1 | L22: 2.2
A23: Alimentação
A24: Rótulo | D24: CUPÃO DE DESCONTO NA PROZIS | I24: Ganhos de músculo
A25: Contou Kcal | I25: Mês | J25: homem | L25: mulher
A26: Balança cozinha | D26: http://prozis.com/nBW7 | I26: Iniciantes | J26: 1 | K26: 1.5 | L26: 0.5 | M26: 0.75
A27: Sono | I27: Intermediários | J27: 0.5 | K27: 1 | L27: 0.25 | M27: 0.5
A28: Hidratação | D28: Pontos Chave Alimentação | I28: Avançados | J28: 0.25 | K28: 0.5 | L28: 0.125 | M28: 0.25
A29: Compromisso | D29: 20-40g Proteina por refeição (ou 0,25-0,4g/kg) entre cada 3-4h | I29: gramas/semana | J29: homem | L29: mulher
A30: Perspectiva | D30: 3-6 refeições por dia | I30: Iniciantes | J30: =J26%*B6/4.2*1000 -> 0 | K30: =K26%*B6/4.2*1000 -> 0 | L30: =L26%*B6/4.2*1000 -> 0 | M30: =M26%*B6/4.2*1000 -> 0
D31: 40-50% dos hidratos diários consumidos nas refeições antes e depois do treino | I31: Intermediários | J31: =J27%*B6/4.2*1000 -> 0 | K31: =K27%*B6/4.2*1000 -> 0 | L31: =L27%*B6/4.2*1000 -> 0 | M31: =M27%*B6/4.2*1000 -> 0
D32: Consumir 10g de Fibra por cada 1000kcal | I32: Avançados | J32: =J28%*B6/4.2*1000 -> 0 | K32: =K28%*B6/4.2*1000 -> 0 | L32: =L28%*B6/4.2*1000 -> 0 | M32: =M28%*B6/4.2*1000 -> 0
D33: 2 Porções de fruta e 2 de Vegetais
I34: Perda peso
D35: Refeição até uma hora antes do treino | I35: Mês | J35: % peso a perder | L35: IMC
D36: Mais Hidratos | I36: Obeso | J36: 3 | K36: 4 | L36: =B6/(B7*B7*0.0001) -> #DIV/0!
D37: Menos Gordura | I37: Excesso peso | J37: 2 | K37: 3
D38: Menos Fibra | I38: Normal | J38: 1 | K38: 2
D39: Razoavel Proteina | I39: Atlético | J39: 0.5 | K39: 1
I40: Gramas perdidas por semana
I41: Obeso | J41: =J36%*B6*1000 -> 0 | K41: =K36%*B6*1000 -> 0
...

Sheet Controle de medidas
A1: Data | C1: Semana | D1: Fase | E1: diário | F1: média | G1: Dif | H1: % | I1: Passos | K1: Horas de sono | M1: Stress | N1: Energia | O1: Fome | P1: Meta | Q1: ingerido | R1: média | S1: diferença | T1: Hidratos (gr) | U1: Meta Hidratos | V1: Média semanal | W1: Proteína (gr) | X1: Meta Proteína | Y1: Média semanal | Z1: Gordura (gr) | AA1: Meta Gordura | AB1: Média semanal | AC1: Fibra
E2: Peso | I2: diário | J2: média | K2: diário | L2: média | M2: (1-5) | N2: (1-5) | O2: (1-5) | P2: Kcal | T2: Macros
A3: s | C3: 1 | F3: =AVERAGE(E3:E9) -> #DIV/0! | J3: =AVERAGE(I3:I9) -> #DIV/0! | L3: =AVERAGE(K3:K9) -> #DIV/0! | R3: =AVERAGE(Q3:Q9) -> #DIV/0! | S3: =R3-P3 -> #DIV/0! | U3: =(P3-(X3*4+AA3*9))/4 -> 0 | V3: =AVERAGE(T3:T9) -> #DIV/0! | Y3: =AVERAGE(W3:W9) -> #DIV/0! | AB3: =AVERAGE(Z3:Z9) -> #DIV/0!
A4: d | B4: =1+B3 -> 1
A5: s | B5: =1+B4 -> 2
A6: t | B6: =1+B5 -> 3
A7: q | B7: =1+B6 -> 4
A8: q | B8: =1+B7 -> 5
A9: s | B9: =1+B8 -> 6
A10: s | B10: =1+B9 -> 7 | C10: =1+C3 -> 2 | F10: =AVERAGE(E10:E16) -> #DIV/0! | G10: =F10-F3 -> #DIV/0! | H10: =(F10*100/F3)-100 -> #DIV/0! | J10: =AVERAGE(I10:I16) -> #DIV/0! | L10: =AVERAGE(K10:K16) -> #DIV/0! | R10: =AVERAGE(Q10:Q16) -> #DIV/0! | S10: =R10-P10 -> #DIV/0! | U10: =(P10-(X10*4+AA10*9))/4 -> 0 | V10: =AVERAGE(T10:T16) -> #DIV/0! | Y10: =AVERAGE(W10:W16) -> #DIV/0! | AB10: =AVERAGE(Z10:Z16) -> #DIV/0!
A11: d | B11: =1+B10 -> 8
A12: s | B12: =1+B11 -> 9
A13: t | B13: =1+B12 -> 10
A14: q | B14: =1+B13 -> 11
A15: q | B15: =1+B14 -> 12
A16: s | B16: =1+B15 -> 13
A17: s | B17: =1+B16 -> 14 | C17: =1+C10 -> 3 | F17: =AVERAGE(E17:E23) -> #DIV/0! | G17: =F17-F10 -> #DIV/0! | H17: =(F17*100/F10)-100 -> #DIV/0! | J17: =AVERAGE(I17:I23) -> #DIV/0! | L17: =AVERAGE(K17:K23) -> #DIV/0! | R17: =AVERAGE(Q17:Q23) -> #DIV/0! | S17: =R17-P17 -> #DIV/0! | U17: =(P17-(X17*4+AA17*9))/4 -> 0 | V17: =AVERAGE(T17:T23) -> #DIV/0! | Y17: =AVERAGE(W17:W23) -> #DIV/0! | AB17: =AVERAGE(Z17:Z23) -> #DIV/0!
A18: d | B18: =1+B17 -> 15
A19: s | B19: =1+B18 -> 16
A20: t | B20: =1+B19 -> 17
A21: q | B21: =1+B20 -> 18
A22: q | B22: =1+B21 -> 19
A23: s | B23: =1+B22 -> 20
A24: s | B24: =1+B23 -> 21 | C24: =1+C17 -> 4 | F24: =AVERAGE(E24:E30) -> #DIV/0! | G24: =F24-F17 -> #DIV/0! | H24: =(F24*100/F17)-100 -> #DIV/0! | J24: =AVERAGE(I24:I30) -> #DIV/0! | L24: =AVERAGE(K24:K30) -> #DIV/0! | R24: =AVERAGE(Q24:Q30) -> #DIV/0! | S24: =R24-P24 -> #DIV/0! | U24: =(P24-(X24*4+AA24*9))/4 -> 0 | V24: =AVERAGE(T24:T30) -> #DIV/0! | Y24: =AVERAGE(W24:W30) -> #DIV/0! | AB24: =AVERAGE(Z24:Z30) -> #DIV/0!
A25: d | B25: =1+B24 -> 22
A26: s | B26: =1+B25 -> 23
A27: t | B27: =1+B26 -> 24
A28: q | B28: =1+B27 -> 25
A29: q | B29: =1+B28 -> 26
A30: s | B30: =1+B29 -> 27
A31: s | B31: =1+B30 -> 28 | C31: =1+C24 -> 5 | F31: =AVERAGE(E31:E37) -> #DIV/0! | G31: =F31-F24 -> #DIV/0! | H31: =(F31*100/F24)-100 -> #DIV/0! | J31: =AVERAGE(I31:I37) -> #DIV/0! | L31: =AVERAGE(K31:K37) -> #DIV/0! | R31: =AVERAGE(Q31:Q37) -> #DIV/0! | S31: =R31-P31 -> #DIV/0! | U31: =(P31-(X31*4+AA31*9))/4 -> 0 | V31: =AVERAGE(T31:T37) -> #DIV/0! | Y31: =AVERAGE(W31:W37) -> #DIV/0! | AB31: =AVERAGE(Z31:Z37) -> #DIV/0!
A32: d | B32: =1+B31 -> 29
A33: s | B33: =1+B32 -> 30
A34: t | B34: =1+B33 -> 31
A35: q | B35: =1+B34 -> 32
A36: q | B36: =1+B35 -> 33
A37: s | B37: =1+B36 -> 34
A38: s | B38: =1+B37 -> 35 | C38: =1+C31 -> 6 | F38: =AVERAGE(E38:E44) -> #DIV/0! | G38: =F38-F31 -> #DIV/0! | H38: =(F38*100/F31)-100 -> #DIV/0! | J38: =AVERAGE(I38:I44) -> #DIV/0! | L38: =AVERAGE(K38:K44) -> #DIV/0! | R38: =AVERAGE(Q38:Q44) -> #DIV/0! | S38: =R38-P38 -> #DIV/0! | U38: =(P38-(X38*4+AA38*9))/4 -> 0 | V38: =AVERAGE(T38:T44) -> #DIV/0! | Y38: =AVERAGE(W38:W44) -> #DIV/0! | AB38: =AVERAGE(Z38:Z44) -> #DIV/0!
A39: d | B39: =1+B38 -> 36
A40: s | B40: =1+B39 -> 37
...

Sheet Perimetros
A1: Perimetros
D2: Objectivo:
D3: Data proximo update:
A4: Diferenças | C4: =C8-C7 -> 0 | D4: =D8-D7 -> 0 | E4: =E8-E7 -> 0 | F4: =F8-F7 -> 0 | H4: =H8-H7 -> 0 | K4: =K8-K7 -> 0
A6: Semana | B6: Data | C6: Peso | D6: Cintura | E6: Glúteo | F6: Coxa Drt. | G6: Coxa Esq. | H6: Braço Drt. | I6: Braço Esq. | J6: Gémeo Drt | K6: Gémeo Esq.

Sheet Plano treino
H1: Plano de Treino | Q1: Semana 1 | AE1: Semana 2 | AT1: Semana 3 | BI1: Semana 4 | BX1: Semana 5 | CM1: Semana 6 | DB1: Semana 7 | DQ1: Semana 8
Q2: Power inicial | R2: 1 | U2: 2 | X2: 3 | AA2: 4 | AD2: Total | AE2: Power inicial | AF2: 1 | AI2: 2 | AL2: 3 | AO2: 4 | AR2: Total | AT2: Power inicial | AU2: 1 | AX2: 2 | BA2: 3 | BD2: 4 | BG2: Total | BI2: Power inicial | BJ2: 1 | BM2: 2 | BP2: 3 | BS2: 4 | BV2: Total | BX2: Power inicial | BY2: 1 | CB2: 2 | CE2: 3 | CH2: 4 | CK2: Total | CM2: Power inicial | CN2: 1 | CQ2: 2 | CT2: 3 | CW2: 4 | CZ2: Total | DB2: Power inicial | DC2: 1 | DF2: 2 | DI2: 3 | DL2: 4 | DO2: Total | DQ2: Power inicial | DR2: 1 | DU2: 2 | DX2: 3 | EA2: 4 | ED2: Total
A3: 1 | B3: 1 | C3: 1 | D3: 0.5 | E3: 0.5 | F3: 0.3 | H3: MÚSCULO | I3: TOTAL DE SERIES | K3: TREINO | L3: EXERCÍCIO | M3: Video | N3: Séries | O3: Reps | P3: Descanso | R3: R | S3: C | T3: F | U3: R | V3: C | W3: F | X3: R | Y3: C | Z3: F | AA3: R | AB3: C | AC3: F | AF3: R | AG3: C | AH3: F | AI3: R | AJ3: C | AK3: F | AL3: R | AM3: C | AN3: F | AO3: R | AP3: C | AQ3: F | AR3: Sem. | AS3: Dif. | AU3: R | AV3: C | AW3: F | AX3: R | AY3: C | AZ3: F | BA3: R | BB3: C | BC3: F | BD3: R | BE3: C | BF3: F | BG3: Sem. | BH3: Dif. | BJ3: R | BK3: C | BL3: F | BM3: R | BN3: C | BO3: F | BP3: R | BQ3: C | BR3: F | BS3: R | BT3: C | BU3: F | BV3: Sem. | BW3: Dif. | BY3: R | BZ3: C | CA3: F | CB3: R | CC3: C | CD3: F | CE3: R | CF3: C | CG3: F | CH3: R | CI3: C | CJ3: F | CK3: Sem. | CL3: Dif. | CN3: R | CO3: C | CP3: F | CQ3: R | CR3: C | CS3: F | CT3: R | CU3: C | CV3: F | CW3: R | CX3: C | CY3: F | CZ3: Sem. | DA3: Dif. | DC3: R | DD3: C | DE3: F | DF3: R | DG3: C | DH3: F | DI3: R | DJ3: C | DK3: F | DL3: R | DM3: C | DN3: F | DO3: Sem. | DP3: Dif. | DR3: R | DS3: C | DT3: F | DU3: R | DV3: C | DW3: F | DX3: R | DY3: C | DZ3: F | EA3: R | EB3: C | EC3: F | ED3: Sem. | EE3: Dif.
A4: =IFERROR(VLOOKUP(L4,'Base dados Exercicios'!$C$4:$J$305,3,FALSE),"") | B4: =IFERROR(VLOOKUP(L4,'Base dados Exercicios'!$C$4:$J$305,4,FALSE),"") | C4: =IFERROR(VLOOKUP(L4,'Base dados Exercicios'!$C$4:$J$305,5,FALSE),"") | D4: =IFERROR(VLOOKUP(L4,'Base dados Exercicios'!$C$4:$J$305,6,FALSE),"") | E4: =IFERROR(VLOOKUP(L4,'Base dados Exercicios'!$C$4:$J$305,7,FALSE),"") | F4: =IFERROR(VLOOKUP(L4,'Base dados Exercicios'!$C$4:$J$305,8,FALSE),"") | H4: ='Base dados Exercicios'!L4 -> Biceps | I4: =SUMIF($A$4:$A$102,H4,$N$4:$N$102)+SUMIF($B$4:B$102,H4,$N$4:$N$102)+SUMIF($C$4:$C$102,H4,$N$4:$N$102)+(SUMIF($D$4:$D$102,H4,$N$4:$N$102)*0.5)+(SUMIF($E$4:$E$102,H4,$N$4:$N$102)*0.5)+(SUMIF($F$4:F$102,H4,$N$4:$N$102)*0.3) -> 0 | K4: 1 | M4: =IF(L4<>"", HYPERLINK(VLOOKUP(L4,'Base dados Exercicios'!$C$4:$D$83,2,FALSE),"Check"),"") | AD4: =(R4*S4)+(U4*V4)+(X4*Y4)+(AA4*AB4) -> 0 | AR4: =(AF4*AG4)+(AI4*AJ4)+(AL4*AM4)+(AO4*AP4) -> 0 | AS4: =AR4-AD4 -> 0 | BG4: =(AU4*AV4)+(AX4*AY4)+(BA4*BB4)+(BD4*BE4) -> 0 | BH4: =BG4-AR4 -> 0 | BV4: =(BJ4*BK4)+(BM4*BN4)+(BP4*BQ4)+(BS4*BT4) -> 0 | BW4: =BV4-BG4 -> 0 | CK4: =(BY4*BZ4)+(CB4*CC4)+(CE4*CF4)+(CH4*CI4) -> 0 | CL4: =CK4-BV4 -> 0 | CZ4: =(CN4*CO4)+(CQ4*CR4)+(CT4*CU4)+(CW4*CX4) -> 0 | DA4: =CZ4-CK4 -> 0 | DO4: =(DC4*DD4)+(DF4*DG4)+(DI4*DJ4)+(DL4*DM4) -> 0 | DP4: =DO4-CZ4 -> 0 | ED4: =(DR4*DS4)+(DU4*DV4)+(DX4*DY4)+(EA4*EB4) -> 0 | EE4: =ED4-DO4 -> 0
A5: =IFERROR(VLOOKUP(L5,'Base dados Exercicios'!$C$4:$J$305,3,FALSE),"") | B5: =IFERROR(VLOOKUP(L5,'Base dados Exercicios'!$C$4:$J$305,4,FALSE),"") | C5: =IFERROR(VLOOKUP(L5,'Base dados Exercicios'!$C$4:$J$305,5,FALSE),"") | D5: =IFERROR(VLOOKUP(L5,'Base dados Exercicios'!$C$4:$J$305,6,FALSE),"") | E5: =IFERROR(VLOOKUP(L5,'Base dados Exercicios'!$C$4:$J$305,7,FALSE),"") | F5: =IFERROR(VLOOKUP(L5,'Base dados Exercicios'!$C$4:$J$305,8,FALSE),"") | H5: ='Base dados Exercicios'!L5 -> Dorsal | I5: =SUMIF($A$4:$A$102,H5,$N$4:$N$102)+SUMIF($B$4:B$102,H5,$N$4:$N$102)+SUMIF($C$4:$C$102,H5,$N$4:$N$102)+(SUMIF($D$4:$D$102,H5,$N$4:$N$102)*0.5)+(SUMIF($E$4:$E$102,H5,$N$4:$N$102)*0.5)+(SUMIF($F$4:F$102,H5,$N$4:$N$102)*0.3) -> 0 | M5: =IF(L5<>"", HYPERLINK(VLOOKUP(L5,'Base dados Exercicios'!$C$4:$D$83,2,FALSE),"Check"),"") | AD5: =(R5*S5)+(U5*V5)+(X5*Y5)+(AA5*AB5) -> 0 | AR5: =(AF5*AG5)+(AI5*AJ5)+(AL5*AM5)+(AO5*AP5) -> 0 | AS5: =AR5-AD5 -> 0 | BG5: =(AU5*AV5)+(AX5*AY5)+(BA5*BB5)+(BD5*BE5) -> 0 | BH5: =BG5-AR5 -> 0 | BV5: =(BJ5*BK5)+(BM5*BN5)+(BP5*BQ5)+(BS5*BT5) -> 0 | BW5: =BV5-BG5 -> 0 | CK5: =(BY5*BZ5)+(CB5*CC5)+(CE5*CF5)+(CH5*CI5) -> 0 | CL5: =CK5-BV5 -> 0 | CZ5: =(CN5*CO5)+(CQ5*CR5)+(CT5*CU5)+(CW5*CX5) -> 0 | DA5: =CZ5-CK5 -> 0 | DO5: =(DC5*DD5)+(DF5*DG5)+(DI5*DJ5)+(DL5*DM5) -> 0 | DP5: =DO5-CZ5 -> 0 | ED5: =(DR5*DS5)+(DU5*DV5)+(DX5*DY5)+(EA5*EB5) -> 0 | EE5: =ED5-DO5 -> 0
A6: =IFERROR(VLOOKUP(L6,'Base dados Exercicios'!$C$4:$J$305,3,FALSE),"") | B6: =IFERROR(VLOOKUP(L6,'Base dados Exercicios'!$C$4:$J$305,4,FALSE),"") | C6: =IFERROR(VLOOKUP(L6,'Base dados Exercicios'!$C$4:$J$305,5,FALSE),"") | D6: =IFERROR(VLOOKUP(L6,'Base dados Exercicios'!$C$4:$J$305,6,FALSE),"") | E6: =IFERROR(VLOOKUP(L6,'Base dados Exercicios'!$C$4:$J$305,7,FALSE),"") | F6: =IFERROR(VLOOKUP(L6,'Base dados Exercicios'!$C$4:$J$305,8,FALSE),"") | H6: ='Base dados Exercicios'!L6 -> Ombro frontal | I6: =SUMIF($A$4:$A$102,H6,$N$4:$N$102)+SUMIF($B$4:B$102,H6,$N$4:$N$102)+SUMIF($C$4:$C$102,H6,$N$4:$N$102)+(SUMIF($D$4:$D$102,H6,$N$4:$N$102)*0.5)+(SUMIF($E$4:$E$102,H6,$N$4:$N$102)*0.5)+(SUMIF($F$4:F$102,H6,$N$4:$N$102)*0.3) -> 0 | M6: =IF(L6<>"", HYPERLINK(VLOOKUP(L6,'Base dados Exercicios'!$C$4:$D$83,2,FALSE),"Check"),"") | AD6: =(R6*S6)+(U6*V6)+(X6*Y6)+(AA6*AB6) -> 0 | AR6: =(AF6*AG6)+(AI6*AJ6)+(AL6*AM6)+(AO6*AP6) -> 0 | AS6: =AR6-AD6 -> 0 | BG6: =(AU6*AV6)+(AX6*AY6)+(BA6*BB6)+(BD6*BE6) -> 0 | BH6: =BG6-AR6 -> 0 | BV6: =(BJ6*BK6)+(BM6*BN6)+(BP6*BQ6)+(BS6*BT6) -> 0 | BW6: =BV6-BG6 -> 0 | CK6: =(BY6*BZ6)+(CB6*CC6)+(CE6*CF6)+(CH6*CI6) -> 0 | CL6: =CK6-BV6 -> 0 | CZ6: =(CN6*CO6)+(CQ6*CR6)+(CT6*CU6)+(CW6*CX6) -> 0 | DA6: =CZ6-CK6 -> 0 | DO6: =(DC6*DD6)+(DF6*DG6)+(DI6*DJ6)+(DL6*DM6) -> 0 | DP6: =DO6-CZ6 -> 0 | ED6: =(DR6*DS6)+(DU6*DV6)+(DX6*DY6)+(EA6*EB6) -> 0 | EE6: =ED6-DO6 -> 0
A7: =IFERROR(VLOOKUP(L7,'Base dados Exercicios'!$C$4:$J$305,3,FALSE),"") | B7: =IFERROR(VLOOKUP(L7,'Base dados Exercicios'!$C$4:$J$305,4,FALSE),"") | C7: =IFERROR(VLOOKUP(L7,'Base dados Exercicios'!$C$4:$J$305,5,FALSE),"") | D7: =IFERROR(VLOOKUP(L7,'Base dados Exercicios'!$C$4:$J$305,6,FALSE),"") | E7: =IFERROR(VLOOKUP(L7,'Base dados Exercicios'!$C$4:$J$305,7,FALSE),"") | F7: =IFERROR(VLOOKUP(L7,'Base dados Exercicios'!$C$4:$J$305,8,FALSE),"") | H7: ='Base dados Exercicios'!L11 -> Triceps | I7: =SUMIF($A$4:$A$102,H7,$N$4:$N$102)+SUMIF($B$4:B$102,H7,$N$4:$N$102)+SUMIF($C$4:$C$102,H7,$N$4:$N$102)+(SUMIF($D$4:$D$102,H7,$N$4:$N$102)*0.5)+(SUMIF($E$4:$E$102,H7,$N$4:$N$102)*0.5)+(SUMIF($F$4:F$102,H7,$N$4:$N$102)*0.3) -> 0 | M7: =IF(L7<>"", HYPERLINK(VLOOKUP(L7,'Base dados Exercicios'!$C$4:$D$83,2,FALSE),"Check"),"") | AD7: =(R7*S7)+(U7*V7)+(X7*Y7)+(AA7*AB7) -> 0 | AR7: =(AF7*AG7)+(AI7*AJ7)+(AL7*AM7)+(AO7*AP7) -> 0 | AS7: =AR7-AD7 -> 0 | BG7: =(AU7*AV7)+(AX7*AY7)+(BA7*BB7)+(BD7*BE7) -> 0 | BH7: =BG7-AR7 -> 0 | BV7: =(BJ7*BK7)+(BM7*BN7)+(BP7*BQ7)+(BS7*BT7) -> 0 | BW7: =BV7-BG7 -> 0 | CK7: =(BY7*BZ7)+(CB7*CC7)+(CE7*CF7)+(CH7*CI7) -> 0 | CL7: =CK7-BV7 -> 0 | CZ7: =(CN7*CO7)+(CQ7*CR7)+(CT7*CU7)+(CW7*CX7) -> 0 | DA7: =CZ7-CK7 -> 0 | DO7: =(DC7*DD7)+(DF7*DG7)+(DI7*DJ7)+(DL7*DM7) -> 0 | DP7: =DO7-CZ7 -> 0 | ED7: =(DR7*DS7)+(DU7*DV7)+(DX7*DY7)+(EA7*EB7) -> 0 | EE7: =ED7-DO7 -> 0
A8: =IFERROR(VLOOKUP(L8,'Base dados Exercicios'!$C$4:$J$305,3,FALSE),"") | B8: =IFERROR(VLOOKUP(L8,'Base dados Exercicios'!$C$4:$J$305,4,FALSE),"") | C8: =IFERROR(VLOOKUP(L8,'Base dados Exercicios'!$C$4:$J$305,5,FALSE),"") | D8: =IFERROR(VLOOKUP(L8,'Base dados Exercicios'!$C$4:$J$305,6,FALSE),"") | E8: =IFERROR(VLOOKUP(L8,'Base dados Exercicios'!$C$4:$J$305,7,FALSE),"") | F8: =IFERROR(VLOOKUP(L8,'Base dados Exercicios'!$C$4:$J$305,8,FALSE),"") | H8: ='Base dados Exercicios'!L9 -> Peito | I8: =SUMIF($A$4:$A$102,H8,$N$4:$N$102)+SUMIF($B$4:B$102,H8,$N$4:$N$102)+SUMIF($C$4:$C$102,H8,$N$4:$N$102)+(SUMIF($D$4:$D$102,H8,$N$4:$N$102)*0.5)+(SUMIF($E$4:$E$102,H8,$N$4:$N$102)*0.5)+(SUMIF($F$4:F$102,H8,$N$4:$N$102)*0.3) -> 0 | M8: =IF(L8<>"", HYPERLINK(VLOOKUP(L8,'Base dados Exercicios'!$C$4:$D$83,2,FALSE),"Check"),"") | AD8: =(R8*S8)+(U8*V8)+(X8*Y8)+(AA8*AB8) -> 0 | AR8: =(AF8*AG8)+(AI8*AJ8)+(AL8*AM8)+(AO8*AP8) -> 0 | AS8: =AR8-AD8 -> 0 | BG8: =(AU8*AV8)+(AX8*AY8)+(BA8*BB8)+(BD8*BE8) -> 0 | BH8: =BG8-AR8 -> 0 | BV8: =(BJ8*BK8)+(BM8*BN8)+(BP8*BQ8)+(BS8*BT8) -> 0 | BW8: =BV8-BG8 -> 0 | CK8: =(BY8*BZ8)+(CB8*CC8)+(CE8*CF8)+(CH8*CI8) -> 0 | CL8: =CK8-BV8 -> 0 | CZ8: =(CN8*CO8)+(CQ8*CR8)+(CT8*CU8)+(CW8*CX8) -> 0 | DA8: =CZ8-CK8 -> 0 | DO8: =(DC8*DD8)+(DF8*DG8)+(DI8*DJ8)+(DL8*DM8) -> 0 | DP8: =DO8-CZ8 -> 0 | ED8: =(DR8*DS8)+(DU8*DV8)+(DX8*DY8)+(EA8*EB8) -> 0 | EE8: =ED8-DO8 -> 0
A9: =IFERROR(VLOOKUP(L9,'Base dados Exercicios'!$C$4:$J$305,3,FALSE),"") | B9: =IFERROR(VLOOKUP(L9,'Base dados Exercicios'!$C$4:$J$305,4,FALSE),"") | C9: =IFERROR(VLOOKUP(L9,'Base dados Exercicios'!$C$4:$J$305,5,FALSE),"") | D9: =IFERROR(VLOOKUP(L9,'Base dados Exercicios'!$C$4:$J$305,6,FALSE),"") | E9: =IFERROR(VLOOKUP(L9,'Base dados Exercicios'!$C$4:$J$305,7,FALSE),"") | F9: =IFERROR(VLOOKUP(L9,'Base dados Exercicios'!$C$4:$J$305,8,FALSE),"") | H9: ='Base dados Exercicios'!L8 -> Ombro posterior | I9: =SUMIF($A$4:$A$102,H9,$N$4:$N$102)+SUMIF($B$4:B$102,H9,$N$4:$N$102)+SUMIF($C$4:$C$102,H9,$N$4:$N$102)+(SUMIF($D$4:$D$102,H9,$N$4:$N$102)*0.5)+(SUMIF($E$4:$E$102,H9,$N$4:$N$102)*0.5)+(SUMIF($F$4:F$102,H9,$N$4:$N$102)*0.3) -> 0 | M9: =IF(L9<>"", HYPERLINK(VLOOKUP(L9,'Base dados Exercicios'!$C$4:$D$83,2,FALSE),"Check"),"") | AD9: =(R9*S9)+(U9*V9)+(X9*Y9)+(AA9*AB9) -> 0 | AR9: =(AF9*AG9)+(AI9*AJ9)+(AL9*AM9)+(AO9*AP9) -> 0 | AS9: =AR9-AD9 -> 0 | BG9: =(AU9*AV9)+(AX9*AY9)+(BA9*BB9)+(BD9*BE9) -> 0 | BH9: =BG9-AR9 -> 0 | BV9: =(BJ9*BK9)+(BM9*BN9)+(BP9*BQ9)+(BS9*BT9) -> 0 | BW9: =BV9-BG9 -> 0 | CK9: =(BY9*BZ9)+(CB9*CC9)+(CE9*CF9)+(CH9*CI9) -> 0 | CL9: =CK9-BV9 -> 0 | CZ9: =(CN9*CO9)+(CQ9*CR9)+(CT9*CU9)+(CW9*CX9) -> 0 | DA9: =CZ9-CK9 -> 0 | DO9: =(DC9*DD9)+(DF9*DG9)+(DI9*DJ9)+(DL9*DM9) -> 0 | DP9: =DO9-CZ9 -> 0 | ED9: =(DR9*DS9)+(DU9*DV9)+(DX9*DY9)+(EA9*EB9) -> 0 | EE9: =ED9-DO9 -> 0
A10: =IFERROR(VLOOKUP(L10,'Base dados Exercicios'!$C$4:$J$305,3,FALSE),"") | B10: =IFERROR(VLOOKUP(L10,'Base dados Exercicios'!$C$4:$J$305,4,FALSE),"") | C10: =IFERROR(VLOOKUP(L10,'Base dados Exercicios'!$C$4:$J$305,5,FALSE),"") | D10: =IFERROR(VLOOKUP(L10,'Base dados Exercicios'!$C$4:$J$305,6,FALSE),"") | E10: =IFERROR(VLOOKUP(L10,'Base dados Exercicios'!$C$4:$J$305,7,FALSE),"") | F10: =IFERROR(VLOOKUP(L10,'Base dados Exercicios'!$C$4:$J$305,8,FALSE),"") | H10: ='Base dados Exercicios'!L7 -> Ombro médio | I10: =SUMIF($A$4:$A$102,H10,$N$4:$N$102)+SUMIF($B$4:B$102,H10,$N$4:$N$102)+SUMIF($C$4:$C$102,H10,$N$4:$N$102)+(SUMIF($D$4:$D$102,H10,$N$4:$N$102)*0.5)+(SUMIF($E$4:$E$102,H10,$N$4:$N$102)*0.5)+(SUMIF($F$4:F$102,H10,$N$4:$N$102)*0.3) -> 0 | M10: =IF(L10<>"", HYPERLINK(VLOOKUP(L10,'Base dados Exercicios'!$C$4:$D$83,2,FALSE),"Check"),"") | AD10: =(R10*S10)+(U10*V10)+(X10*Y10)+(AA10*AB10) -> 0 | AR10: =(AF10*AG10)+(AI10*AJ10)+(AL10*AM10)+(AO10*AP10) -> 0 | AS10: =AR10-AD10 -> 0 | BG10: =(AU10*AV10)+(AX10*AY10)+(BA10*BB10)+(BD10*BE10) -> 0 | BH10: =BG10-AR10 -> 0 | BV10: =(BJ10*BK10)+(BM10*BN10)+(BP10*BQ10)+(BS10*BT10) -> 0 | BW10: =BV10-BG10 -> 0 | CK10: =(BY10*BZ10)+(CB10*CC10)+(CE10*CF10)+(CH10*CI10) -> 0 | CL10: =CK10-BV10 -> 0 | CZ10: =(CN10*CO10)+(CQ10*CR10)+(CT10*CU10)+(CW10*CX10) -> 0 | DA10: =CZ10-CK10 -> 0 | DO10: =(DC10*DD10)+(DF10*DG10)+(DI10*DJ10)+(DL10*DM10) -> 0 | DP10: =DO10-CZ10 -> 0 | ED10: =(DR10*DS10)+(DU10*DV10)+(DX10*DY10)+(EA10*EB10) -> 0 | EE10: =ED10-DO10 -> 0
A11: =IFERROR(VLOOKUP(L11,'Base dados Exercicios'!$C$4:$J$305,3,FALSE),"") | B11: =IFERROR(VLOOKUP(L11,'Base dados Exercicios'!$C$4:$J$305,4,FALSE),"") | C11: =IFERROR(VLOOKUP(L11,'Base dados Exercicios'!$C$4:$J$305,5,FALSE),"") | D11: =IFERROR(VLOOKUP(L11,'Base dados Exercicios'!$C$4:$J$305,6,FALSE),"") | E11: =IFERROR(VLOOKUP(L11,'Base dados Exercicios'!$C$4:$J$305,7,FALSE),"") | F11: =IFERROR(VLOOKUP(L11,'Base dados Exercicios'!$C$4:$J$305,8,FALSE),"") | H11: ='Base dados Exercicios'!L10 -> Trapézio | I11: =SUMIF($A$4:$A$102,H11,$N$4:$N$102)+SUMIF($B$4:B$102,H11,$N$4:$N$102)+SUMIF($C$4:$C$102,H11,$N$4:$N$102)+(SUMIF($D$4:$D$102,H11,$N$4:$N$102)*0.5)+(SUMIF($E$4:$E$102,H11,$N$4:$N$102)*0.5)+(SUMIF($F$4:F$102,H11,$N$4:$N$102)*0.3) -> 0 | M11: =IF(L11<>"", HYPERLINK(VLOOKUP(L11,'Base dados Exercicios'!$C$4:$D$83,2,FALSE),"Check"),"") | AD11: =(R11*S11)+(U11*V11)+(X11*Y11)+(AA11*AB11) -> 0 | AR11: =(AF11*AG11)+(AI11*AJ11)+(AL11*AM11)+(AO11*AP11) -> 0 | AS11: =AR11-AD11 -> 0 | BG11: =(AU11*AV11)+(AX11*AY11)+(BA11*BB11)+(BD11*BE11) -> 0 | BH11: =BG11-AR11 -> 0 | BV11: =(BJ11*BK11)+(BM11*BN11)+(BP11*BQ11)+(BS11*BT11) -> 0 | BW11: =BV11-BG11 -> 0 | CK11: =(BY11*BZ11)+(CB11*CC11)+(CE11*CF11)+(CH11*CI11) -> 0 | CL11: =CK11-BV11 -> 0 | CZ11: =(CN11*CO11)+(CQ11*CR11)+(CT11*CU11)+(CW11*CX11) -> 0 | DA11: =CZ11-CK11 -> 0 | DO11: =(DC11*DD11)+(DF11*DG11)+(DI11*DJ11)+(DL11*DM11) -> 0 | DP11: =DO11-CZ11 -> 0 | ED11: =(DR11*DS11)+(DU11*DV11)+(DX11*DY11)+(EA11*EB11) -> 0 | EE11: =ED11-DO11 -> 0
A12: =IFERROR(VLOOKUP(L12,'Base dados Exercicios'!$C$4:$J$305,3,FALSE),"") | B12: =IFERROR(VLOOKUP(L12,'Base dados Exercicios'!$C$4:$J$305,4,FALSE),"") | C12: =IFERROR(VLOOKUP(L12,'Base dados Exercicios'!$C$4:$J$305,5,FALSE),"") | D12: =IFERROR(VLOOKUP(L12,'Base dados Exercicios'!$C$4:$J$305,6,FALSE),"") | E12: =IFERROR(VLOOKUP(L12,'Base dados Exercicios'!$C$4:$J$305,7,FALSE),"") | F12: =IFERROR(VLOOKUP(L12,'Base dados Exercicios'!$C$4:$J$305,8,FALSE),"") | H12: ='Base dados Exercicios'!L12 -> Quadriceps | I12: =SUMIF($A$4:$A$102,H12,$N$4:$N$102)+SUMIF($B$4:B$102,H12,$N$4:$N$102)+SUMIF($C$4:$C$102,H12,$N$4:$N$102)+(SUMIF($D$4:$D$102,H12,$N$4:$N$102)*0.5)+(SUMIF($E$4:$E$102,H12,$N$4:$N$102)*0.5)+(SUMIF($F$4:F$102,H12,$N$4:$N$102)*0.3) -> 0 | M12: =IF(L12<>"", HYPERLINK(VLOOKUP(L12,'Base dados Exercicios'!$C$4:$D$83,2,FALSE),"Check"),"") | AD12: =(R12*S12)+(U12*V12)+(X12*Y12)+(AA12*AB12) -> 0 | AR12: =(AF12*AG12)+(AI12*AJ12)+(AL12*AM12)+(AO12*AP12) -> 0 | AS12: =AR12-AD12 -> 0 | BG12: =(AU12*AV12)+(AX12*AY12)+(BA12*BB12)+(BD12*BE12) -> 0 | BH12: =BG12-AR12 -> 0 | BV12: =(BJ12*BK12)+(BM12*BN12)+(BP12*BQ12)+(BS12*BT12) -> 0 | BW12: =BV12-BG12 -> 0 | CK12: =(BY12*BZ12)+(CB12*CC12)+(CE12*CF12)+(CH12*CI12) -> 0 | CL12: =CK12-BV12 -> 0 | CZ12: =(CN12*CO12)+(CQ12*CR12)+(CT12*CU12)+(CW12*CX12) -> 0 | DA12: =CZ12-CK12 -> 0 | DO12: =(DC12*DD12)+(DF12*DG12)+(DI12*DJ12)+(DL12*DM12) -> 0 | DP12: =DO12-CZ12 -> 0 | ED12: =(DR12*DS12)+(DU12*DV12)+(DX12*DY12)+(EA12*EB12) -> 0 | EE12: =ED12-DO12 -> 0
A13: =IFERROR(VLOOKUP(L13,'Base dados Exercicios'!$C$4:$J$305,3,FALSE),"") | B13: =IFERROR(VLOOKUP(L13,'Base dados Exercicios'!$C$4:$J$305,4,FALSE),"") | C13: =IFERROR(VLOOKUP(L13,'Base dados Exercicios'!$C$4:$J$305,5,FALSE),"") | D13: =IFERROR(VLOOKUP(L13,'Base dados Exercicios'!$C$4:$J$305,6,FALSE),"") | E13: =IFERROR(VLOOKUP(L13,'Base dados Exercicios'!$C$4:$J$305,7,FALSE),"") | F13: =IFERROR(VLOOKUP(L13,'Base dados Exercicios'!$C$4:$J$305,8,FALSE),"") | H13: ='Base dados Exercicios'!L13 -> Posterior de coxa | I13: =SUMIF($A$4:$A$102,H13,$N$4:$N$102)+SUMIF($B$4:B$102,H13,$N$4:$N$102)+SUMIF($C$4:$C$102,H13,$N$4:$N$102)+(SUMIF($D$4:$D$102,H13,$N$4:$N$102)*0.5)+(SUMIF($E$4:$E$102,H13,$N$4:$N$102)*0.5)+(SUMIF($F$4:F$102,H13,$N$4:$N$102)*0.3) -> 0 | M13: =IF(L13<>"", HYPERLINK(VLOOKUP(L13,'Base dados Exercicios'!$C$4:$D$83,2,FALSE),"Check"),"") | Q13: NOTAS: | AE13: NOTAS: | AT13: NOTAS: | BI13: NOTAS: | BX13: NOTAS: | CM13: NOTAS: | DB13: NOTAS: | DQ13: NOTAS:
A14: =IFERROR(VLOOKUP(L14,'Base dados Exercicios'!$C$4:$J$305,3,FALSE),"") | B14: =IFERROR(VLOOKUP(L14,'Base dados Exercicios'!$C$4:$J$305,4,FALSE),"") | C14: =IFERROR(VLOOKUP(L14,'Base dados Exercicios'!$C$4:$J$305,5,FALSE),"") | D14: =IFERROR(VLOOKUP(L14,'Base dados Exercicios'!$C$4:$J$305,6,FALSE),"") | E14: =IFERROR(VLOOKUP(L14,'Base dados Exercicios'!$C$4:$J$305,7,FALSE),"") | F14: =IFERROR(VLOOKUP(L14,'Base dados Exercicios'!$C$4:$J$305,8,FALSE),"") | H14: ='Base dados Exercicios'!L14 -> Glúteo | I14: =SUMIF($A$4:$A$102,H14,$N$4:$N$102)+SUMIF($B$4:B$102,H14,$N$4:$N$102)+SUMIF($C$4:$C$102,H14,$N$4:$N$102)+(SUMIF($D$4:$D$102,H14,$N$4:$N$102)*0.5)+(SUMIF($E$4:$E$102,H14,$N$4:$N$102)*0.5)+(SUMIF($F$4:F$102,H14,$N$4:$N$102)*0.3) -> 0 | K14: 2 | M14: =IF(L14<>"", HYPERLINK(VLOOKUP(L14,'Base dados Exercicios'!$C$4:$D$83,2,FALSE),"Check"),"") | AD14: =(R14*S14)+(U14*V14)+(X14*Y14)+(AA14*AB14) -> 0 | AR14: =(AF14*AG14)+(AI14*AJ14)+(AL14*AM14)+(AO14*AP14) -> 0 | AS14: =AR14-AD14 -> 0 | BG14: =(AU14*AV14)+(AX14*AY14)+(BA14*BB14)+(BD14*BE14) -> 0 | BH14: =BG14-AR14 -> 0 | BV14: =(BJ14*BK14)+(BM14*BN14)+(BP14*BQ14)+(BS14*BT14) -> 0 | BW14: =BV14-BG14 -> 0 | CK14: =(BY14*BZ14)+(CB14*CC14)+(CE14*CF14)+(CH14*CI14) -> 0 | CL14: =CK14-BV14 -> 0 | CZ14: =(CN14*CO14)+(CQ14*CR14)+(CT14*CU14)+(CW14*CX14) -> 0 | DA14: =CZ14-CK14 -> 0 | DO14: =(DC14*DD14)+(DF14*DG14)+(DI14*DJ14)+(DL14*DM14) -> 0 | DP14: =DO14-CZ14 -> 0 | ED14: =(DR14*DS14)+(DU14*DV14)+(DX14*DY14)+(EA14*EB14) -> 0 | EE14: =ED14-DO14 -> 0
A15: =IFERROR(VLOOKUP(L15,'Base dados Exercicios'!$C$4:$J$305,3,FALSE),"") | B15: =IFERROR(VLOOKUP(L15,'Base dados Exercicios'!$C$4:$J$305,4,FALSE),"") | C15: =IFERROR(VLOOKUP(L15,'Base dados Exercicios'!$C$4:$J$305,5,FALSE),"") | D15: =IFERROR(VLOOKUP(L15,'Base dados Exercicios'!$C$4:$J$305,6,FALSE),"") | E15: =IFERROR(VLOOKUP(L15,'Base dados Exercicios'!$C$4:$J$305,7,FALSE),"") | F15: =IFERROR(VLOOKUP(L15,'Base dados Exercicios'!$C$4:$J$305,8,FALSE),"") | H15: ='Base dados Exercicios'!L15 -> Lombares | I15: =SUMIF($A$4:$A$102,H15,$N$4:$N$102)+SUMIF($B$4:B$102,H15,$N$4:$N$102)+SUMIF($C$4:$C$102,H15,$N$4:$N$102)+(SUMIF($D$4:$D$102,H15,$N$4:$N$102)*0.5)+(SUMIF($E$4:$E$102,H15,$N$4:$N$102)*0.5)+(SUMIF($F$4:F$102,H15,$N$4:$N$102)*0.3) -> 0 | M15: =IF(L15<>"", HYPERLINK(VLOOKUP(L15,'Base dados Exercicios'!$C$4:$D$83,2,FALSE),"Check"),"") | AD15: =(R15*S15)+(U15*V15)+(X15*Y15)+(AA15*AB15) -> 0 | AR15: =(AF15*AG15)+(AI15*AJ15)+(AL15*AM15)+(AO15*AP15) -> 0 | AS15: =AR15-AD15 -> 0 | BG15: =(AU15*AV15)+(AX15*AY15)+(BA15*BB15)+(BD15*BE15) -> 0 | BH15: =BG15-AR15 -> 0 | BV15: =(BJ15*BK15)+(BM15*BN15)+(BP15*BQ15)+(BS15*BT15) -> 0 | BW15: =BV15-BG15 -> 0 | CK15: =(BY15*BZ15)+(CB15*CC15)+(CE15*CF15)+(CH15*CI15) -> 0 | CL15: =CK15-BV15 -> 0 | CZ15: =(CN15*CO15)+(CQ15*CR15)+(CT15*CU15)+(CW15*CX15) -> 0 | DA15: =CZ15-CK15 -> 0 | DO15: =(DC15*DD15)+(DF15*DG15)+(DI15*DJ15)+(DL15*DM15) -> 0 | DP15: =DO15-CZ15 -> 0 | ED15: =(DR15*DS15)+(DU15*DV15)+(DX15*DY15)+(EA15*EB15) -> 0 | EE15: =ED15-DO15 -> 0
A16: =IFERROR(VLOOKUP(L16,'Base dados Exercicios'!$C$4:$J$305,3,FALSE),"") | B16: =IFERROR(VLOOKUP(L16,'Base dados Exercicios'!$C$4:$J$305,4,FALSE),"") | C16: =IFERROR(VLOOKUP(L16,'Base dados Exercicios'!$C$4:$J$305,5,FALSE),"") | D16: =IFERROR(VLOOKUP(L16,'Base dados Exercicios'!$C$4:$J$305,6,FALSE),"") | E16: =IFERROR(VLOOKUP(L16,'Base dados Exercicios'!$C$4:$J$305,7,FALSE),"") | F16: =IFERROR(VLOOKUP(L16,'Base dados Exercicios'!$C$4:$J$305,8,FALSE),"") | H16: ='Base dados Exercicios'!L16 -> Gémeos | I16: =SUMIF($A$4:$A$102,H16,$N$4:$N$102)+SUMIF($B$4:B$102,H16,$N$4:$N$102)+SUMIF($C$4:$C$102,H16,$N$4:$N$102)+(SUMIF($D$4:$D$102,H16,$N$4:$N$102)*0.5)+(SUMIF($E$4:$E$102,H16,$N$4:$N$102)*0.5)+(SUMIF($F$4:F$102,H16,$N$4:$N$102)*0.3) -> 0 | M16: =IF(L16<>"", HYPERLINK(VLOOKUP(L16,'Base dados Exercicios'!$C$4:$D$83,2,FALSE),"Check"),"") | AD16: =(R16*S16)+(U16*V16)+(X16*Y16)+(AA16*AB16) -> 0 | AR16: =(AF16*AG16)+(AI16*AJ16)+(AL16*AM16)+(AO16*AP16) -> 0 | AS16: =AR16-AD16 -> 0 | BG16: =(AU16*AV16)+(AX16*AY16)+(BA16*BB16)+(BD16*BE16) -> 0 | BH16: =BG16-AR16 -> 0 | BV16: =(BJ16*BK16)+(BM16*BN16)+(BP16*BQ16)+(BS16*BT16) -> 0 | BW16: =BV16-BG16 -> 0 | CK16: =(BY16*BZ16)+(CB16*CC16)+(CE16*CF16)+(CH16*CI16) -> 0 | CL16: =CK16-BV16 -> 0 | CZ16: =(CN16*CO16)+(CQ16*CR16)+(CT16*CU16)+(CW16*CX16) -> 0 | DA16: =CZ16-CK16 -> 0 | DO16: =(DC16*DD16)+(DF16*DG16)+(DI16*DJ16)+(DL16*DM16) -> 0 | DP16: =DO16-CZ16 -> 0 | ED16: =(DR16*DS16)+(DU16*DV16)+(DX16*DY16)+(EA16*EB16) -> 0 | EE16: =ED16-DO16 -> 0
A17: =IFERROR(VLOOKUP(L17,'Base dados Exercicios'!$C$4:$J$305,3,FALSE),"") | B17: =IFERROR(VLOOKUP(L17,'Base dados Exercicios'!$C$4:$J$305,4,FALSE),"") | C17: =IFERROR(VLOOKUP(L17,'Base dados Exercicios'!$C$4:$J$305,5,FALSE),"") | D17: =IFERROR(VLOOKUP(L17,'Base dados Exercicios'!$C$4:$J$305,6,FALSE),"") | E17: =IFERROR(VLOOKUP(L17,'Base dados Exercicios'!$C$4:$J$305,7,FALSE),"") | F17: =IFERROR(VLOOKUP(L17,'Base dados Exercicios'!$C$4:$J$305,8,FALSE),"") | M17: =IF(L17<>"", HYPERLINK(VLOOKUP(L17,'Base dados Exercicios'!$C$4:$D$83,2,FALSE),"Check"),"") | AD17: =(R17*S17)+(U17*V17)+(X17*Y17)+(AA17*AB17) -> 0 | AR17: =(AF17*AG17)+(AI17*AJ17)+(AL17*AM17)+(AO17*AP17) -> 0 | AS17: =AR17-AD17 -> 0 | BG17: =(AU17*AV17)+(AX17*AY17)+(BA17*BB17)+(BD17*BE17) -> 0 | BH17: =BG17-AR17 -> 0 | BV17: =(BJ17*BK17)+(BM17*BN17)+(BP17*BQ17)+(BS17*BT17) -> 0 | BW17: =BV17-BG17 -> 0 | CK17: =(BY17*BZ17)+(CB17*CC17)+(CE17*CF17)+(CH17*CI17) -> 0 | CL17: =CK17-BV17 -> 0 | CZ17: =(CN17*CO17)+(CQ17*CR17)+(CT17*CU17)+(CW17*CX17) -> 0 | DA17: =CZ17-CK17 -> 0 | DO17: =(DC17*DD17)+(DF17*DG17)+(DI17*DJ17)+(DL17*DM17) -> 0 | DP17: =DO17-CZ17 -> 0 | ED17: =(DR17*DS17)+(DU17*DV17)+(DX17*DY17)+(EA17*EB17) -> 0 | EE17: =ED17-DO17 -> 0
A18: =IFERROR(VLOOKUP(L18,'Base dados Exercicios'!$C$4:$J$305,3,FALSE),"") | B18: =IFERROR(VLOOKUP(L18,'Base dados Exercicios'!$C$4:$J$305,4,FALSE),"") | C18: =IFERROR(VLOOKUP(L18,'Base dados Exercicios'!$C$4:$J$305,5,FALSE),"") | D18: =IFERROR(VLOOKUP(L18,'Base dados Exercicios'!$C$4:$J$305,6,FALSE),"") | E18: =IFERROR(VLOOKUP(L18,'Base dados Exercicios'!$C$4:$J$305,7,FALSE),"") | F18: =IFERROR(VLOOKUP(L18,'Base dados Exercicios'!$C$4:$J$305,8,FALSE),"") | H18: Cardio | M18: =IF(L18<>"", HYPERLINK(VLOOKUP(L18,'Base dados Exercicios'!$C$4:$D$83,2,FALSE),"Check"),"") | AD18: =(R18*S18)+(U18*V18)+(X18*Y18)+(AA18*AB18) -> 0 | AR18: =(AF18*AG18)+(AI18*AJ18)+(AL18*AM18)+(AO18*AP18) -> 0 | AS18: =AR18-AD18 -> 0 | BG18: =(AU18*AV18)+(AX18*AY18)+(BA18*BB18)+(BD18*BE18) -> 0 | BH18: =BG18-AR18 -> 0 | BV18: =(BJ18*BK18)+(BM18*BN18)+(BP18*BQ18)+(BS18*BT18) -> 0 | BW18: =BV18-BG18 -> 0 | CK18: =(BY18*BZ18)+(CB18*CC18)+(CE18*CF18)+(CH18*CI18) -> 0 | CL18: =CK18-BV18 -> 0 | CZ18: =(CN18*CO18)+(CQ18*CR18)+(CT18*CU18)+(CW18*CX18) -> 0 | DA18: =CZ18-CK18 -> 0 | DO18: =(DC18*DD18)+(DF18*DG18)+(DI18*DJ18)+(DL18*DM18) -> 0 | DP18: =DO18-CZ18 -> 0 | ED18: =(DR18*DS18)+(DU18*DV18)+(DX18*DY18)+(EA18*EB18) -> 0 | EE18: =ED18-DO18 -> 0
A19: =IFERROR(VLOOKUP(L19,'Base dados Exercicios'!$C$4:$J$305,3,FALSE),"") | B19: =IFERROR(VLOOKUP(L19,'Base dados Exercicios'!$C$4:$J$305,4,FALSE),"") | C19: =IFERROR(VLOOKUP(L19,'Base dados Exercicios'!$C$4:$J$305,5,FALSE),"") | D19: =IFERROR(VLOOKUP(L19,'Base dados Exercicios'!$C$4:$J$305,6,FALSE),"") | E19: =IFERROR(VLOOKUP(L19,'Base dados Exercicios'!$C$4:$J$305,7,FALSE),"") | F19: =IFERROR(VLOOKUP(L19,'Base dados Exercicios'!$C$4:$J$305,8,FALSE),"") | M19: =IF(L19<>"", HYPERLINK(VLOOKUP(L19,'Base dados Exercicios'!$C$4:$D$83,2,FALSE),"Check"),"") | AD19: =(R19*S19)+(U19*V19)+(X19*Y19)+(AA19*AB19) -> 0 | AR19: =(AF19*AG19)+(AI19*AJ19)+(AL19*AM19)+(AO19*AP19) -> 0 | AS19: =AR19-AD19 -> 0 | BG19: =(AU19*AV19)+(AX19*AY19)+(BA19*BB19)+(BD19*BE19) -> 0 | BH19: =BG19-AR19 -> 0 | BV19: =(BJ19*BK19)+(BM19*BN19)+(BP19*BQ19)+(BS19*BT19) -> 0 | BW19: =BV19-BG19 -> 0 | CK19: =(BY19*BZ19)+(CB19*CC19)+(CE19*CF19)+(CH19*CI19) -> 0 | CL19: =CK19-BV19 -> 0 | CZ19: =(CN19*CO19)+(CQ19*CR19)+(CT19*CU19)+(CW19*CX19) -> 0 | DA19: =CZ19-CK19 -> 0 | DO19: =(DC19*DD19)+(DF19*DG19)+(DI19*DJ19)+(DL19*DM19) -> 0 | DP19: =DO19-CZ19 -> 0 | ED19: =(DR19*DS19)+(DU19*DV19)+(DX19*DY19)+(EA19*EB19) -> 0 | EE19: =ED19-DO19 -> 0
A20: =IFERROR(VLOOKUP(L20,'Base dados Exercicios'!$C$4:$J$305,3,FALSE),"") | B20: =IFERROR(VLOOKUP(L20,'Base dados Exercicios'!$C$4:$J$305,4,FALSE),"") | C20: =IFERROR(VLOOKUP(L20,'Base dados Exercicios'!$C$4:$J$305,5,FALSE),"") | D20: =IFERROR(VLOOKUP(L20,'Base dados Exercicios'!$C$4:$J$305,6,FALSE),"") | E20: =IFERROR(VLOOKUP(L20,'Base dados Exercicios'!$C$4:$J$305,7,FALSE),"") | F20: =IFERROR(VLOOKUP(L20,'Base dados Exercicios'!$C$4:$J$305,8,FALSE),"") | M20: =IF(L20<>"", HYPERLINK(VLOOKUP(L20,'Base dados Exercicios'!$C$4:$D$83,2,FALSE),"Check"),"") | AD20: =(R20*S20)+(U20*V20)+(X20*Y20)+(AA20*AB20) -> 0 | AR20: =(AF20*AG20)+(AI20*AJ20)+(AL20*AM20)+(AO20*AP20) -> 0 | AS20: =AR20-AD20 -> 0 | BG20: =(AU20*AV20)+(AX20*AY20)+(BA20*BB20)+(BD20*BE20) -> 0 | BH20: =BG20-AR20 -> 0 | BV20: =(BJ20*BK20)+(BM20*BN20)+(BP20*BQ20)+(BS20*BT20) -> 0 | BW20: =BV20-BG20 -> 0 | CK20: =(BY20*BZ20)+(CB20*CC20)+(CE20*CF20)+(CH20*CI20) -> 0 | CL20: =CK20-BV20 -> 0 | CZ20: =(CN20*CO20)+(CQ20*CR20)+(CT20*CU20)+(CW20*CX20) -> 0 | DA20: =CZ20-CK20 -> 0 | DO20: =(DC20*DD20)+(DF20*DG20)+(DI20*DJ20)+(DL20*DM20) -> 0 | DP20: =DO20-CZ20 -> 0 | ED20: =(DR20*DS20)+(DU20*DV20)+(DX20*DY20)+(EA20*EB20) -> 0 | EE20: =ED20-DO20 -> 0
A21: =IFERROR(VLOOKUP(L21,'Base dados Exercicios'!$C$4:$J$305,3,FALSE),"") | B21: =IFERROR(VLOOKUP(L21,'Base dados Exercicios'!$C$4:$J$305,4,FALSE),"") | C21: =IFERROR(VLOOKUP(L21,'Base dados Exercicios'!$C$4:$J$305,5,FALSE),"") | D21: =IFERROR(VLOOKUP(L21,'Base dados Exercicios'!$C$4:$J$305,6,FALSE),"") | E21: =IFERROR(VLOOKUP(L21,'Base dados Exercicios'!$C$4:$J$305,7,FALSE),"") | F21: =IFERROR(VLOOKUP(L21,'Base dados Exercicios'!$C$4:$J$305,8,FALSE),"") | M21: =IF(L21<>"", HYPERLINK(VLOOKUP(L21,'Base dados Exercicios'!$C$4:$D$83,2,FALSE),"Check"),"") | AD21: =(R21*S21)+(U21*V21)+(X21*Y21)+(AA21*AB21) -> 0 | AR21: =(AF21*AG21)+(AI21*AJ21)+(AL21*AM21)+(AO21*AP21) -> 0 | AS21: =AR21-AD21 -> 0 | BG21: =(AU21*AV21)+(AX21*AY21)+(BA21*BB21)+(BD21*BE21) -> 0 | BH21: =BG21-AR21 -> 0 | BV21: =(BJ21*BK21)+(BM21*BN21)+(BP21*BQ21)+(BS21*BT21) -> 0 | BW21: =BV21-BG21 -> 0 | CK21: =(BY21*BZ21)+(CB21*CC21)+(CE21*CF21)+(CH21*CI21) -> 0 | CL21: =CK21-BV21 -> 0 | CZ21: =(CN21*CO21)+(CQ21*CR21)+(CT21*CU21)+(CW21*CX21) -> 0 | DA21: =CZ21-CK21 -> 0 | DO21: =(DC21*DD21)+(DF21*DG21)+(DI21*DJ21)+(DL21*DM21) -> 0 | DP21: =DO21-CZ21 -> 0 | ED21: =(DR21*DS21)+(DU21*DV21)+(DX21*DY21)+(EA21*EB21) -> 0 | EE21: =ED21-DO21 -> 0
A22: =IFERROR(VLOOKUP(L22,'Base dados Exercicios'!$C$4:$J$305,3,FALSE),"") | B22: =IFERROR(VLOOKUP(L22,'Base dados Exercicios'!$C$4:$J$305,4,FALSE),"") | C22: =IFERROR(VLOOKUP(L22,'Base dados Exercicios'!$C$4:$J$305,5,FALSE),"") | D22: =IFERROR(VLOOKUP(L22,'Base dados Exercicios'!$C$4:$J$305,6,FALSE),"") | E22: =IFERROR(VLOOKUP(L22,'Base dados Exercicios'!$C$4:$J$305,7,FALSE),"") | F22: =IFERROR(VLOOKUP(L22,'Base dados Exercicios'!$C$4:$J$305,8,FALSE),"") | M22: =IF(L22<>"", HYPERLINK(VLOOKUP(L22,'Base dados Exercicios'!$C$4:$D$83,2,FALSE),"Check"),"") | AD22: =(R22*S22)+(U22*V22)+(X22*Y22)+(AA22*AB22) -> 0 | AR22: =(AF22*AG22)+(AI22*AJ22)+(AL22*AM22)+(AO22*AP22) -> 0 | AS22: =AR22-AD22 -> 0 | BG22: =(AU22*AV22)+(AX22*AY22)+(BA22*BB22)+(BD22*BE22) -> 0 | BH22: =BG22-AR22 -> 0 | BV22: =(BJ22*BK22)+(BM22*BN22)+(BP22*BQ22)+(BS22*BT22) -> 0 | BW22: =BV22-BG22 -> 0 | CK22: =(BY22*BZ22)+(CB22*CC22)+(CE22*CF22)+(CH22*CI22) -> 0 | CL22: =CK22-BV22 -> 0 | CZ22: =(CN22*CO22)+(CQ22*CR22)+(CT22*CU22)+(CW22*CX22) -> 0 | DA22: =CZ22-CK22 -> 0 | DO22: =(DC22*DD22)+(DF22*DG22)+(DI22*DJ22)+(DL22*DM22) -> 0 | DP22: =DO22-CZ22 -> 0 | ED22: =(DR22*DS22)+(DU22*DV22)+(DX22*DY22)+(EA22*EB22) -> 0 | EE22: =ED22-DO22 -> 0
A23: =IFERROR(VLOOKUP(L23,'Base dados Exercicios'!$C$4:$J$305,3,FALSE),"") | B23: =IFERROR(VLOOKUP(L23,'Base dados Exercicios'!$C$4:$J$305,4,FALSE),"") | C23: =IFERROR(VLOOKUP(L23,'Base dados Exercicios'!$C$4:$J$305,5,FALSE),"") | D23: =IFERROR(VLOOKUP(L23,'Base dados Exercicios'!$C$4:$J$305,6,FALSE),"") | E23: =IFERROR(VLOOKUP(L23,'Base dados Exercicios'!$C$4:$J$305,7,FALSE),"") | F23: =IFERROR(VLOOKUP(L23,'Base dados Exercicios'!$C$4:$J$305,8,FALSE),"") | H23: Dia 1 | M23: =IF(L23<>"", HYPERLINK(VLOOKUP(L23,'Base dados Exercicios'!$C$4:$D$83,2,FALSE),"Check"),"") | Q23: NOTAS: | AE23: NOTAS: | AT23: NOTAS: | BI23: NOTAS: | BX23: NOTAS: | CM23: NOTAS: | DB23: NOTAS: | DQ23: NOTAS:
A24: =IFERROR(VLOOKUP(L24,'Base dados Exercicios'!$C$4:$J$305,3,FALSE),"") | B24: =IFERROR(VLOOKUP(L24,'Base dados Exercicios'!$C$4:$J$305,4,FALSE),"") | C24: =IFERROR(VLOOKUP(L24,'Base dados Exercicios'!$C$4:$J$305,5,FALSE),"") | D24: =IFERROR(VLOOKUP(L24,'Base dados Exercicios'!$C$4:$J$305,6,FALSE),"") | E24: =IFERROR(VLOOKUP(L24,'Base dados Exercicios'!$C$4:$J$305,7,FALSE),"") | F24: =IFERROR(VLOOKUP(L24,'Base dados Exercicios'!$C$4:$J$305,8,FALSE),"") | H24: Dia 2 | K24: =I25 -> 0 | M24: =IF(L24<>"", HYPERLINK(VLOOKUP(L24,'Base dados Exercicios'!$C$4:$D$83,2,FALSE),"Check"),"") | AD24: =(R24*S24)+(U24*V24)+(X24*Y24)+(AA24*AB24) -> 0 | AR24: =(AF24*AG24)+(AI24*AJ24)+(AL24*AM24)+(AO24*AP24) -> 0 | AS24: =AR24-AD24 -> 0 | BG24: =(AU24*AV24)+(AX24*AY24)+(BA24*BB24)+(BD24*BE24) -> 0 | BH24: =BG24-AR24 -> 0 | BV24: =(BJ24*BK24)+(BM24*BN24)+(BP24*BQ24)+(BS24*BT24) -> 0 | BW24: =BV24-BG24 -> 0 | CK24: =(BY24*BZ24)+(CB24*CC24)+(CE24*CF24)+(CH24*CI24) -> 0 | CL24: =CK24-BV24 -> 0 | CZ24: =(CN24*CO24)+(CQ24*CR24)+(CT24*CU24)+(CW24*CX24) -> 0 | DA24: =CZ24-CK24 -> 0 | DO24: =(DC24*DD24)+(DF24*DG24)+(DI24*DJ24)+(DL24*DM24) -> 0 | DP24: =DO24-CZ24 -> 0 | ED24: =(DR24*DS24)+(DU24*DV24)+(DX24*DY24)+(EA24*EB24) -> 0 | EE24: =ED24-DO24 -> 0
A25: =IFERROR(VLOOKUP(L25,'Base dados Exercicios'!$C$4:$J$305,3,FALSE),"") | B25: =IFERROR(VLOOKUP(L25,'Base dados Exercicios'!$C$4:$J$305,4,FALSE),"") | C25: =IFERROR(VLOOKUP(L25,'Base dados Exercicios'!$C$4:$J$305,5,FALSE),"") | D25: =IFERROR(VLOOKUP(L25,'Base dados Exercicios'!$C$4:$J$305,6,FALSE),"") | E25: =IFERROR(VLOOKUP(L25,'Base dados Exercicios'!$C$4:$J$305,7,FALSE),"") | F25: =IFERROR(VLOOKUP(L25,'Base dados Exercicios'!$C$4:$J$305,8,FALSE),"") | H25: Dia 3 | M25: =IF(L25<>"", HYPERLINK(VLOOKUP(L25,'Base dados Exercicios'!$C$4:$D$83,2,FALSE),"Check"),"") | AD25: =(R25*S25)+(U25*V25)+(X25*Y25)+(AA25*AB25) -> 0 | AR25: =(AF25*AG25)+(AI25*AJ25)+(AL25*AM25)+(AO25*AP25) -> 0 | AS25: =AR25-AD25 -> 0 | BG25: =(AU25*AV25)+(AX25*AY25)+(BA25*BB25)+(BD25*BE25) -> 0 | BH25: =BG25-AR25 -> 0 | BV25: =(BJ25*BK25)+(BM25*BN25)+(BP25*BQ25)+(BS25*BT25) -> 0 | BW25: =BV25-BG25 -> 0 | CK25: =(BY25*BZ25)+(CB25*CC25)+(CE25*CF25)+(CH25*CI25) -> 0 | CL25: =CK25-BV25 -> 0 | CZ25: =(CN25*CO25)+(CQ25*CR25)+(CT25*CU25)+(CW25*CX25) -> 0 | DA25: =CZ25-CK25 -> 0 | DO25: =(DC25*DD25)+(DF25*DG25)+(DI25*DJ25)+(DL25*DM25) -> 0 | DP25: =DO25-CZ25 -> 0 | ED25: =(DR25*DS25)+(DU25*DV25)+(DX25*DY25)+(EA25*EB25) -> 0 | EE25: =ED25-DO25 -> 0
A26: =IFERROR(VLOOKUP(L26,'Base dados Exercicios'!$C$4:$J$305,3,FALSE),"") | B26: =IFERROR(VLOOKUP(L26,'Base dados Exercicios'!$C$4:$J$305,4,FALSE),"") | C26: =IFERROR(VLOOKUP(L26,'Base dados Exercicios'!$C$4:$J$305,5,FALSE),"") | D26: =IFERROR(VLOOKUP(L26,'Base dados Exercicios'!$C$4:$J$305,6,FALSE),"") | E26: =IFERROR(VLOOKUP(L26,'Base dados Exercicios'!$C$4:$J$305,7,FALSE),"") | F26: =IFERROR(VLOOKUP(L26,'Base dados Exercicios'!$C$4:$J$305,8,FALSE),"") | H26: Dia 4 | M26: =IF(L26<>"", HYPERLINK(VLOOKUP(L26,'Base dados Exercicios'!$C$4:$D$83,2,FALSE),"Check"),"") | AD26: =(R26*S26)+(U26*V26)+(X26*Y26)+(AA26*AB26) -> 0 | AR26: =(AF26*AG26)+(AI26*AJ26)+(AL26*AM26)+(AO26*AP26) -> 0 | AS26: =AR26-AD26 -> 0 | BG26: =(AU26*AV26)+(AX26*AY26)+(BA26*BB26)+(BD26*BE26) -> 0 | BH26: =BG26-AR26 -> 0 | BV26: =(BJ26*BK26)+(BM26*BN26)+(BP26*BQ26)+(BS26*BT26) -> 0 | BW26: =BV26-BG26 -> 0 | CK26: =(BY26*BZ26)+(CB26*CC26)+(CE26*CF26)+(CH26*CI26) -> 0 | CL26: =CK26-BV26 -> 0 | CZ26: =(CN26*CO26)+(CQ26*CR26)+(CT26*CU26)+(CW26*CX26) -> 0 | DA26: =CZ26-CK26 -> 0 | DO26: =(DC26*DD26)+(DF26*DG26)+(DI26*DJ26)+(DL26*DM26) -> 0 | DP26: =DO26-CZ26 -> 0 | ED26: =(DR26*DS26)+(DU26*DV26)+(DX26*DY26)+(EA26*EB26) -> 0 | EE26: =ED26-DO26 -> 0
A27: =IFERROR(VLOOKUP(L27,'Base dados Exercicios'!$C$4:$J$305,3,FALSE),"") | B27: =IFERROR(VLOOKUP(L27,'Base dados Exercicios'!$C$4:$J$305,4,FALSE),"") | C27: =IFERROR(VLOOKUP(L27,'Base dados Exercicios'!$C$4:$J$305,5,FALSE),"") | D27: =IFERROR(VLOOKUP(L27,'Base dados Exercicios'!$C$4:$J$305,6,FALSE),"") | E27: =IFERROR(VLOOKUP(L27,'Base dados Exercicios'!$C$4:$J$305,7,FALSE),"") | F27: =IFERROR(VLOOKUP(L27,'Base dados Exercicios'!$C$4:$J$305,8,FALSE),"") | H27: Dia 5 | M27: =IF(L27<>"", HYPERLINK(VLOOKUP(L27,'Base dados Exercicios'!$C$4:$D$83,2,FALSE),"Check"),"") | AD27: =(R27*S27)+(U27*V27)+(X27*Y27)+(AA27*AB27) -> 0 | AR27: =(AF27*AG27)+(AI27*AJ27)+(AL27*AM27)+(AO27*AP27) -> 0 | AS27: =AR27-AD27 -> 0 | BG27: =(AU27*AV27)+(AX27*AY27)+(BA27*BB27)+(BD27*BE27) -> 0 | BH27: =BG27-AR27 -> 0 | BV27: =(BJ27*BK27)+(BM27*BN27)+(BP27*BQ27)+(BS27*BT27) -> 0 | BW27: =BV27-BG27 -> 0 | CK27: =(BY27*BZ27)+(CB27*CC27)+(CE27*CF27)+(CH27*CI27) -> 0 | CL27: =CK27-BV27 -> 0 | CZ27: =(CN27*CO27)+(CQ27*CR27)+(CT27*CU27)+(CW27*CX27) -> 0 | DA27: =CZ27-CK27 -> 0 | DO27: =(DC27*DD27)+(DF27*DG27)+(DI27*DJ27)+(DL27*DM27) -> 0 | DP27: =DO27-CZ27 -> 0 | ED27: =(DR27*DS27)+(DU27*DV27)+(DX27*DY27)+(EA27*EB27) -> 0 | EE27: =ED27-DO27 -> 0
A28: =IFERROR(VLOOKUP(L28,'Base dados Exercicios'!$C$4:$J$305,3,FALSE),"") | B28: =IFERROR(VLOOKUP(L28,'Base dados Exercicios'!$C$4:$J$305,4,FALSE),"") | C28: =IFERROR(VLOOKUP(L28,'Base dados Exercicios'!$C$4:$J$305,5,FALSE),"") | D28: =IFERROR(VLOOKUP(L28,'Base dados Exercicios'!$C$4:$J$305,6,FALSE),"") | E28: =IFERROR(VLOOKUP(L28,'Base dados Exercicios'!$C$4:$J$305,7,FALSE),"") | F28: =IFERROR(VLOOKUP(L28,'Base dados Exercicios'!$C$4:$J$305,8,FALSE),"") | H28: Dia 6 | M28: =IF(L28<>"", HYPERLINK(VLOOKUP(L28,'Base dados Exercicios'!$C$4:$D$83,2,FALSE),"Check"),"") | AD28: =(R28*S28)+(U28*V28)+(X28*Y28)+(AA28*AB28) -> 0 | AR28: =(AF28*AG28)+(AI28*AJ28)+(AL28*AM28)+(AO28*AP28) -> 0 | AS28: =AR28-AD28 -> 0 | BG28: =(AU28*AV28)+(AX28*AY28)+(BA28*BB28)+(BD28*BE28) -> 0 | BH28: =BG28-AR28 -> 0 | BV28: =(BJ28*BK28)+(BM28*BN28)+(BP28*BQ28)+(BS28*BT28) -> 0 | BW28: =BV28-BG28 -> 0 | CK28: =(BY28*BZ28)+(CB28*CC28)+(CE28*CF28)+(CH28*CI28) -> 0 | CL28: =CK28-BV28 -> 0 | CZ28: =(CN28*CO28)+(CQ28*CR28)+(CT28*CU28)+(CW28*CX28) -> 0 | DA28: =CZ28-CK28 -> 0 | DO28: =(DC28*DD28)+(DF28*DG28)+(DI28*DJ28)+(DL28*DM28) -> 0 | DP28: =DO28-CZ28 -> 0 | ED28: =(DR28*DS28)+(DU28*DV28)+(DX28*DY28)+(EA28*EB28) -> 0 | EE28: =ED28-DO28 -> 0
A29: =IFERROR(VLOOKUP(L29,'Base dados Exercicios'!$C$4:$J$305,3,FALSE),"") | B29: =IFERROR(VLOOKUP(L29,'Base dados Exercicios'!$C$4:$J$305,4,FALSE),"") | C29: =IFERROR(VLOOKUP(L29,'Base dados Exercicios'!$C$4:$J$305,5,FALSE),"") | D29: =IFERROR(VLOOKUP(L29,'Base dados Exercicios'!$C$4:$J$305,6,FALSE),"") | E29: =IFERROR(VLOOKUP(L29,'Base dados Exercicios'!$C$4:$J$305,7,FALSE),"") | F29: =IFERROR(VLOOKUP(L29,'Base dados Exercicios'!$C$4:$J$305,8,FALSE),"") | H29: Dia 7 | M29: =IF(L29<>"", HYPERLINK(VLOOKUP(L29,'Base dados Exercicios'!$C$4:$D$83,2,FALSE),"Check"),"") | AD29: =(R29*S29)+(U29*V29)+(X29*Y29)+(AA29*AB29) -> 0 | AR29: =(AF29*AG29)+(AI29*AJ29)+(AL29*AM29)+(AO29*AP29) -> 0 | AS29: =AR29-AD29 -> 0 | BG29: =(AU29*AV29)+(AX29*AY29)+(BA29*BB29)+(BD29*BE29) -> 0 | BH29: =BG29-AR29 -> 0 | BV29: =(BJ29*BK29)+(BM29*BN29)+(BP29*BQ29)+(BS29*BT29) -> 0 | BW29: =BV29-BG29 -> 0 | CK29: =(BY29*BZ29)+(CB29*CC29)+(CE29*CF29)+(CH29*CI29) -> 0 | CL29: =CK29-BV29 -> 0 | CZ29: =(CN29*CO29)+(CQ29*CR29)+(CT29*CU29)+(CW29*CX29) -> 0 | DA29: =CZ29-CK29 -> 0 | DO29: =(DC29*DD29)+(DF29*DG29)+(DI29*DJ29)+(DL29*DM29) -> 0 | DP29: =DO29-CZ29 -> 0 | ED29: =(DR29*DS29)+(DU29*DV29)+(DX29*DY29)+(EA29*EB29) -> 0 | EE29: =ED29-DO29 -> 0
A30: =IFERROR(VLOOKUP(L30,'Base dados Exercicios'!$C$4:$J$305,3,FALSE),"") | B30: =IFERROR(VLOOKUP(L30,'Base dados Exercicios'!$C$4:$J$305,4,FALSE),"") | C30: =IFERROR(VLOOKUP(L30,'Base dados Exercicios'!$C$4:$J$305,5,FALSE),"") | D30: =IFERROR(VLOOKUP(L30,'Base dados Exercicios'!$C$4:$J$305,6,FALSE),"") | E30: =IFERROR(VLOOKUP(L30,'Base dados Exercicios'!$C$4:$J$305,7,FALSE),"") | F30: =IFERROR(VLOOKUP(L30,'Base dados Exercicios'!$C$4:$J$305,8,FALSE),"") | M30: =IF(L30<>"", HYPERLINK(VLOOKUP(L30,'Base dados Exercicios'!$C$4:$D$83,2,FALSE),"Check"),"") | AD30: =(R30*S30)+(U30*V30)+(X30*Y30)+(AA30*AB30) -> 0 | AR30: =(AF30*AG30)+(AI30*AJ30)+(AL30*AM30)+(AO30*AP30) -> 0 | AS30: =AR30-AD30 -> 0 | BG30: =(AU30*AV30)+(AX30*AY30)+(BA30*BB30)+(BD30*BE30) -> 0 | BH30: =BG30-AR30 -> 0 | BV30: =(BJ30*BK30)+(BM30*BN30)+(BP30*BQ30)+(BS30*BT30) -> 0 | BW30: =BV30-BG30 -> 0 | CK30: =(BY30*BZ30)+(CB30*CC30)+(CE30*CF30)+(CH30*CI30) -> 0 | CL30: =CK30-BV30 -> 0 | CZ30: =(CN30*CO30)+(CQ30*CR30)+(CT30*CU30)+(CW30*CX30) -> 0 | DA30: =CZ30-CK30 -> 0 | DO30: =(DC30*DD30)+(DF30*DG30)+(DI30*DJ30)+(DL30*DM30) -> 0 | DP30: =DO30-CZ30 -> 0 | ED30: =(DR30*DS30)+(DU30*DV30)+(DX30*DY30)+(EA30*EB30) -> 0 | EE30: =ED30-DO30 -> 0
A31: =IFERROR(VLOOKUP(L31,'Base dados Exercicios'!$C$4:$J$305,3,FALSE),"") | B31: =IFERROR(VLOOKUP(L31,'Base dados Exercicios'!$C$4:$J$305,4,FALSE),"") | C31: =IFERROR(VLOOKUP(L31,'Base dados Exercicios'!$C$4:$J$305,5,FALSE),"") | D31: =IFERROR(VLOOKUP(L31,'Base dados Exercicios'!$C$4:$J$305,6,FALSE),"") | E31: =IFERROR(VLOOKUP(L31,'Base dados Exercicios'!$C$4:$J$305,7,FALSE),"") | F31: =IFERROR(VLOOKUP(L31,'Base dados Exercicios'!$C$4:$J$305,8,FALSE),"") | H31: NOTAS IMPORTANTES | M31: =IF(L31<>"", HYPERLINK(VLOOKUP(L31,'Base dados Exercicios'!$C$4:$D$83,2,FALSE),"Check"),"") | AD31: =(R31*S31)+(U31*V31)+(X31*Y31)+(AA31*AB31) -> 0 | AR31: =(AF31*AG31)+(AI31*AJ31)+(AL31*AM31)+(AO31*AP31) -> 0 | AS31: =AR31-AD31 -> 0 | BG31: =(AU31*AV31)+(AX31*AY31)+(BA31*BB31)+(BD31*BE31) -> 0 | BH31: =BG31-AR31 -> 0 | BV31: =(BJ31*BK31)+(BM31*BN31)+(BP31*BQ31)+(BS31*BT31) -> 0 | BW31: =BV31-BG31 -> 0 | CK31: =(BY31*BZ31)+(CB31*CC31)+(CE31*CF31)+(CH31*CI31) -> 0 | CL31: =CK31-BV31 -> 0 | CZ31: =(CN31*CO31)+(CQ31*CR31)+(CT31*CU31)+(CW31*CX31) -> 0 | DA31: =CZ31-CK31 -> 0 | DO31: =(DC31*DD31)+(DF31*DG31)+(DI31*DJ31)+(DL31*DM31) -> 0 | DP31: =DO31-CZ31 -> 0 | ED31: =(DR31*DS31)+(DU31*DV31)+(DX31*DY31)+(EA31*EB31) -> 0 | EE31: =ED31-DO31 -> 0
A32: =IFERROR(VLOOKUP(L32,'Base dados Exercicios'!$C$4:$J$305,3,FALSE),"") | B32: =IFERROR(VLOOKUP(L32,'Base dados Exercicios'!$C$4:$J$305,4,FALSE),"") | C32: =IFERROR(VLOOKUP(L32,'Base dados Exercicios'!$C$4:$J$305,5,FALSE),"") | D32: =IFERROR(VLOOKUP(L32,'Base dados Exercicios'!$C$4:$J$305,6,FALSE),"") | E32: =IFERROR(VLOOKUP(L32,'Base dados Exercicios'!$C$4:$J$305,7,FALSE),"") | F32: =IFERROR(VLOOKUP(L32,'Base dados Exercicios'!$C$4:$J$305,8,FALSE),"") | H32: Aquecimento para primeiro exercicio: 30% da carga, 15 repetições/ 60% da carga, 8-10 repetições/ 80% da carga, 5 a 6 repetições, 100% da carga 2 a 3 repetições https://www.instagram.com/reel/CrWG0H9A7KB/?igshid=YmMyMTA2M2Y= | M32: =IF(L32<>"", HYPERLINK(VLOOKUP(L32,'Base dados Exercicios'!$C$4:$D$83,2,FALSE),"Check"),"") | AD32: =(R32*S32)+(U32*V32)+(X32*Y32)+(AA32*AB32) -> 0 | AR32: =(AF32*AG32)+(AI32*AJ32)+(AL32*AM32)+(AO32*AP32) -> 0 | AS32: =AR32-AD32 -> 0 | BG32: =(AU32*AV32)+(AX32*AY32)+(BA32*BB32)+(BD32*BE32) -> 0 | BH32: =BG32-AR32 -> 0 | BV32: =(BJ32*BK32)+(BM32*BN32)+(BP32*BQ32)+(BS32*BT32) -> 0 | BW32: =BV32-BG32 -> 0 | CK32: =(BY32*BZ32)+(CB32*CC32)+(CE32*CF32)+(CH32*CI32) -> 0 | CL32: =CK32-BV32 -> 0 | CZ32: =(CN32*CO32)+(CQ32*CR32)+(CT32*CU32)+(CW32*CX32) -> 0 | DA32: =CZ32-CK32 -> 0 | DO32: =(DC32*DD32)+(DF32*DG32)+(DI32*DJ32)+(DL32*DM32) -> 0 | DP32: =DO32-CZ32 -> 0 | ED32: =(DR32*DS32)+(DU32*DV32)+(DX32*DY32)+(EA32*EB32) -> 0 | EE32: =ED32-DO32 -> 0
A33: =IFERROR(VLOOKUP(L33,'Base dados Exercicios'!$C$4:$J$305,3,FALSE),"") | B33: =IFERROR(VLOOKUP(L33,'Base dados Exercicios'!$C$4:$J$305,4,FALSE),"") | C33: =IFERROR(VLOOKUP(L33,'Base dados Exercicios'!$C$4:$J$305,5,FALSE),"") | D33: =IFERROR(VLOOKUP(L33,'Base dados Exercicios'!$C$4:$J$305,6,FALSE),"") | E33: =IFERROR(VLOOKUP(L33,'Base dados Exercicios'!$C$4:$J$305,7,FALSE),"") | F33: =IFERROR(VLOOKUP(L33,'Base dados Exercicios'!$C$4:$J$305,8,FALSE),"") | M33: =IF(L33<>"", HYPERLINK(VLOOKUP(L33,'Base dados Exercicios'!$C$4:$D$83,2,FALSE),"Check"),"") | Q33: NOTAS: | AE33: NOTAS: | AT33: NOTAS: | BI33: NOTAS: | BX33: NOTAS: | CM33: NOTAS: | DB33: NOTAS: | DQ33: NOTAS:
A34: =IFERROR(VLOOKUP(L34,'Base dados Exercicios'!$C$4:$J$305,3,FALSE),"") | B34: =IFERROR(VLOOKUP(L34,'Base dados Exercicios'!$C$4:$J$305,4,FALSE),"") | C34: =IFERROR(VLOOKUP(L34,'Base dados Exercicios'!$C$4:$J$305,5,FALSE),"") | D34: =IFERROR(VLOOKUP(L34,'Base dados Exercicios'!$C$4:$J$305,6,FALSE),"") | E34: =IFERROR(VLOOKUP(L34,'Base dados Exercicios'!$C$4:$J$305,7,FALSE),"") | F34: =IFERROR(VLOOKUP(L34,'Base dados Exercicios'!$C$4:$J$305,8,FALSE),"") | K34: =I26 -> 0 | M34: =IF(L34<>"", HYPERLINK(VLOOKUP(L34,'Base dados Exercicios'!$C$4:$D$83,2,FALSE),"Check"),"") | AD34: =(R34*S34)+(U34*V34)+(X34*Y34)+(AA34*AB34) -> 0 | AR34: =(AF34*AG34)+(AI34*AJ34)+(AL34*AM34)+(AO34*AP34) -> 0 | AS34: =AR34-AD34 -> 0 | BG34: =(AU34*AV34)+(AX34*AY34)+(BA34*BB34)+(BD34*BE34) -> 0 | BH34: =BG34-AR34 -> 0 | BV34: =(BJ34*BK34)+(BM34*BN34)+(BP34*BQ34)+(BS34*BT34) -> 0 | BW34: =BV34-BG34 -> 0 | CK34: =(BY34*BZ34)+(CB34*CC34)+(CE34*CF34)+(CH34*CI34) -> 0 | CL34: =CK34-BV34 -> 0 | CZ34: =(CN34*CO34)+(CQ34*CR34)+(CT34*CU34)+(CW34*CX34) -> 0 | DA34: =CZ34-CK34 -> 0 | DO34: =(DC34*DD34)+(DF34*DG34)+(DI34*DJ34)+(DL34*DM34) -> 0 | DP34: =DO34-CZ34 -> 0 | ED34: =(DR34*DS34)+(DU34*DV34)+(DX34*DY34)+(EA34*EB34) -> 0 | EE34: =ED34-DO34 -> 0
A35: =IFERROR(VLOOKUP(L35,'Base dados Exercicios'!$C$4:$J$305,3,FALSE),"") | B35: =IFERROR(VLOOKUP(L35,'Base dados Exercicios'!$C$4:$J$305,4,FALSE),"") | C35: =IFERROR(VLOOKUP(L35,'Base dados Exercicios'!$C$4:$J$305,5,FALSE),"") | D35: =IFERROR(VLOOKUP(L35,'Base dados Exercicios'!$C$4:$J$305,6,FALSE),"") | E35: =IFERROR(VLOOKUP(L35,'Base dados Exercicios'!$C$4:$J$305,7,FALSE),"") | F35: =IFERROR(VLOOKUP(L35,'Base dados Exercicios'!$C$4:$J$305,8,FALSE),"") | M35: =IF(L35<>"", HYPERLINK(VLOOKUP(L35,'Base dados Exercicios'!$C$4:$D$83,2,FALSE),"Check"),"") | AD35: =(R35*S35)+(U35*V35)+(X35*Y35)+(AA35*AB35) -> 0 | AR35: =(AF35*AG35)+(AI35*AJ35)+(AL35*AM35)+(AO35*AP35) -> 0 | AS35: =AR35-AD35 -> 0 | BG35: =(AU35*AV35)+(AX35*AY35)+(BA35*BB35)+(BD35*BE35) -> 0 | BH35: =BG35-AR35 -> 0 | BV35: =(BJ35*BK35)+(BM35*BN35)+(BP35*BQ35)+(BS35*BT35) -> 0 | BW35: =BV35-BG35 -> 0 | CK35: =(BY35*BZ35)+(CB35*CC35)+(CE35*CF35)+(CH35*CI35) -> 0 | CL35: =CK35-BV35 -> 0 | CZ35: =(CN35*CO35)+(CQ35*CR35)+(CT35*CU35)+(CW35*CX35) -> 0 | DA35: =CZ35-CK35 -> 0 | DO35: =(DC35*DD35)+(DF35*DG35)+(DI35*DJ35)+(DL35*DM35) -> 0 | DP35: =DO35-CZ35 -> 0 | ED35: =(DR35*DS35)+(DU35*DV35)+(DX35*DY35)+(EA35*EB35) -> 0 | EE35: =ED35-DO35 -> 0
A36: =IFERROR(VLOOKUP(L36,'Base dados Exercicios'!$C$4:$J$305,3,FALSE),"") | B36: =IFERROR(VLOOKUP(L36,'Base dados Exercicios'!$C$4:$J$305,4,FALSE),"") | C36: =IFERROR(VLOOKUP(L36,'Base dados Exercicios'!$C$4:$J$305,5,FALSE),"") | D36: =IFERROR(VLOOKUP(L36,'Base dados Exercicios'!$C$4:$J$305,6,FALSE),"") | E36: =IFERROR(VLOOKUP(L36,'Base dados Exercicios'!$C$4:$J$305,7,FALSE),"") | F36: =IFERROR(VLOOKUP(L36,'Base dados Exercicios'!$C$4:$J$305,8,FALSE),"") | M36: =IF(L36<>"", HYPERLINK(VLOOKUP(L36,'Base dados Exercicios'!$C$4:$D$83,2,FALSE),"Check"),"") | AD36: =(R36*S36)+(U36*V36)+(X36*Y36)+(AA36*AB36) -> 0 | AR36: =(AF36*AG36)+(AI36*AJ36)+(AL36*AM36)+(AO36*AP36) -> 0 | AS36: =AR36-AD36 -> 0 | BG36: =(AU36*AV36)+(AX36*AY36)+(BA36*BB36)+(BD36*BE36) -> 0 | BH36: =BG36-AR36 -> 0 | BV36: =(BJ36*BK36)+(BM36*BN36)+(BP36*BQ36)+(BS36*BT36) -> 0 | BW36: =BV36-BG36 -> 0 | CK36: =(BY36*BZ36)+(CB36*CC36)+(CE36*CF36)+(CH36*CI36) -> 0 | CL36: =CK36-BV36 -> 0 | CZ36: =(CN36*CO36)+(CQ36*CR36)+(CT36*CU36)+(CW36*CX36) -> 0 | DA36: =CZ36-CK36 -> 0 | DO36: =(DC36*DD36)+(DF36*DG36)+(DI36*DJ36)+(DL36*DM36) -> 0 | DP36: =DO36-CZ36 -> 0 | ED36: =(DR36*DS36)+(DU36*DV36)+(DX36*DY36)+(EA36*EB36) -> 0 | EE36: =ED36-DO36 -> 0
A37: =IFERROR(VLOOKUP(L37,'Base dados Exercicios'!$C$4:$J$305,3,FALSE),"") | B37: =IFERROR(VLOOKUP(L37,'Base dados Exercicios'!$C$4:$J$305,4,FALSE),"") | C37: =IFERROR(VLOOKUP(L37,'Base dados Exercicios'!$C$4:$J$305,5,FALSE),"") | D37: =IFERROR(VLOOKUP(L37,'Base dados Exercicios'!$C$4:$J$305,6,FALSE),"") | E37: =IFERROR(VLOOKUP(L37,'Base dados Exercicios'!$C$4:$J$305,7,FALSE),"") | F37: =IFERROR(VLOOKUP(L37,'Base dados Exercicios'!$C$4:$J$305,8,FALSE),"") | M37: =IF(L37<>"", HYPERLINK(VLOOKUP(L37,'Base dados Exercicios'!$C$4:$D$83,2,FALSE),"Check"),"") | AD37: =(R37*S37)+(U37*V37)+(X37*Y37)+(AA37*AB37) -> 0 | AR37: =(AF37*AG37)+(AI37*AJ37)+(AL37*AM37)+(AO37*AP37) -> 0 | AS37: =AR37-AD37 -> 0 | BG37: =(AU37*AV37)+(AX37*AY37)+(BA37*BB37)+(BD37*BE37) -> 0 | BH37: =BG37-AR37 -> 0 | BV37: =(BJ37*BK37)+(BM37*BN37)+(BP37*BQ37)+(BS37*BT37) -> 0 | BW37: =BV37-BG37 -> 0 | CK37: =(BY37*BZ37)+(CB37*CC37)+(CE37*CF37)+(CH37*CI37) -> 0 | CL37: =CK37-BV37 -> 0 | CZ37: =(CN37*CO37)+(CQ37*CR37)+(CT37*CU37)+(CW37*CX37) -> 0 | DA37: =CZ37-CK37 -> 0 | DO37: =(DC37*DD37)+(DF37*DG37)+(DI37*DJ37)+(DL37*DM37) -> 0 | DP37: =DO37-CZ37 -> 0 | ED37: =(DR37*DS37)+(DU37*DV37)+(DX37*DY37)+(EA37*EB37) -> 0 | EE37: =ED37-DO37 -> 0
A38: =IFERROR(VLOOKUP(L38,'Base dados Exercicios'!$C$4:$J$305,3,FALSE),"") | B38: =IFERROR(VLOOKUP(L38,'Base dados Exercicios'!$C$4:$J$305,4,FALSE),"") | C38: =IFERROR(VLOOKUP(L38,'Base dados Exercicios'!$C$4:$J$305,5,FALSE),"") | D38: =IFERROR(VLOOKUP(L38,'Base dados Exercicios'!$C$4:$J$305,6,FALSE),"") | E38: =IFERROR(VLOOKUP(L38,'Base dados Exercicios'!$C$4:$J$305,7,FALSE),"") | F38: =IFERROR(VLOOKUP(L38,'Base dados Exercicios'!$C$4:$J$305,8,FALSE),"") | H38: As séries do treino são séries de trabalho, deves ficar entre as 2 e as 0 repetições da falhga muscular | M38: =IF(L38<>"", HYPERLINK(VLOOKUP(L38,'Base dados Exercicios'!$C$4:$D$83,2,FALSE),"Check"),"") | AD38: =(R38*S38)+(U38*V38)+(X38*Y38)+(AA38*AB38) -> 0 | AR38: =(AF38*AG38)+(AI38*AJ38)+(AL38*AM38)+(AO38*AP38) -> 0 | AS38: =AR38-AD38 -> 0 | BG38: =(AU38*AV38)+(AX38*AY38)+(BA38*BB38)+(BD38*BE38) -> 0 | BH38: =BG38-AR38 -> 0 | BV38: =(BJ38*BK38)+(BM38*BN38)+(BP38*BQ38)+(BS38*BT38) -> 0 | BW38: =BV38-BG38 -> 0 | CK38: =(BY38*BZ38)+(CB38*CC38)+(CE38*CF38)+(CH38*CI38) -> 0 | CL38: =CK38-BV38 -> 0 | CZ38: =(CN38*CO38)+(CQ38*CR38)+(CT38*CU38)+(CW38*CX38) -> 0 | DA38: =CZ38-CK38 -> 0 | DO38: =(DC38*DD38)+(DF38*DG38)+(DI38*DJ38)+(DL38*DM38) -> 0 | DP38: =DO38-CZ38 -> 0 | ED38: =(DR38*DS38)+(DU38*DV38)+(DX38*DY38)+(EA38*EB38) -> 0 | EE38: =ED38-DO38 -> 0
A39: =IFERROR(VLOOKUP(L39,'Base dados Exercicios'!$C$4:$J$305,3,FALSE),"") | B39: =IFERROR(VLOOKUP(L39,'Base dados Exercicios'!$C$4:$J$305,4,FALSE),"") | C39: =IFERROR(VLOOKUP(L39,'Base dados Exercicios'!$C$4:$J$305,5,FALSE),"") | D39: =IFERROR(VLOOKUP(L39,'Base dados Exercicios'!$C$4:$J$305,6,FALSE),"") | E39: =IFERROR(VLOOKUP(L39,'Base dados Exercicios'!$C$4:$J$305,7,FALSE),"") | F39: =IFERROR(VLOOKUP(L39,'Base dados Exercicios'!$C$4:$J$305,8,FALSE),"") | M39: =IF(L39<>"", HYPERLINK(VLOOKUP(L39,'Base dados Exercicios'!$C$4:$D$83,2,FALSE),"Check"),"") | AD39: =(R39*S39)+(U39*V39)+(X39*Y39)+(AA39*AB39) -> 0 | AR39: =(AF39*AG39)+(AI39*AJ39)+(AL39*AM39)+(AO39*AP39) -> 0 | AS39: =AR39-AD39 -> 0 | BG39: =(AU39*AV39)+(AX39*AY39)+(BA39*BB39)+(BD39*BE39) -> 0 | BH39: =BG39-AR39 -> 0 | BV39: =(BJ39*BK39)+(BM39*BN39)+(BP39*BQ39)+(BS39*BT39) -> 0 | BW39: =BV39-BG39 -> 0 | CK39: =(BY39*BZ39)+(CB39*CC39)+(CE39*CF39)+(CH39*CI39) -> 0 | CL39: =CK39-BV39 -> 0 | CZ39: =(CN39*CO39)+(CQ39*CR39)+(CT39*CU39)+(CW39*CX39) -> 0 | DA39: =CZ39-CK39 -> 0 | DO39: =(DC39*DD39)+(DF39*DG39)+(DI39*DJ39)+(DL39*DM39) -> 0 | DP39: =DO39-CZ39 -> 0 | ED39: =(DR39*DS39)+(DU39*DV39)+(DX39*DY39)+(EA39*EB39) -> 0 | EE39: =ED39-DO39 -> 0
A40: =IFERROR(VLOOKUP(L40,'Base dados Exercicios'!$C$4:$J$305,3,FALSE),"") | B40: =IFERROR(VLOOKUP(L40,'Base dados Exercicios'!$C$4:$J$305,4,FALSE),"") | C40: =IFERROR(VLOOKUP(L40,'Base dados Exercicios'!$C$4:$J$305,5,FALSE),"") | D40: =IFERROR(VLOOKUP(L40,'Base dados Exercicios'!$C$4:$J$305,6,FALSE),"") | E40: =IFERROR(VLOOKUP(L40,'Base dados Exercicios'!$C$4:$J$305,7,FALSE),"") | F40: =IFERROR(VLOOKUP(L40,'Base dados Exercicios'!$C$4:$J$305,8,FALSE),"") | M40: =IF(L40<>"", HYPERLINK(VLOOKUP(L40,'Base dados Exercicios'!$C$4:$D$83,2,FALSE),"Check"),"") | AD40: =(R40*S40)+(U40*V40)+(X40*Y40)+(AA40*AB40) -> 0 | AR40: =(AF40*AG40)+(AI40*AJ40)+(AL40*AM40)+(AO40*AP40) -> 0 | AS40: =AR40-AD40 -> 0 | BG40: =(AU40*AV40)+(AX40*AY40)+(BA40*BB40)+(BD40*BE40) -> 0 | BH40: =BG40-AR40 -> 0 | BV40: =(BJ40*BK40)+(BM40*BN40)+(BP40*BQ40)+(BS40*BT40) -> 0 | BW40: =BV40-BG40 -> 0 | CK40: =(BY40*BZ40)+(CB40*CC40)+(CE40*CF40)+(CH40*CI40) -> 0 | CL40: =CK40-BV40 -> 0 | CZ40: =(CN40*CO40)+(CQ40*CR40)+(CT40*CU40)+(CW40*CX40) -> 0 | DA40: =CZ40-CK40 -> 0 | DO40: =(DC40*DD40)+(DF40*DG40)+(DI40*DJ40)+(DL40*DM40) -> 0 | DP40: =DO40-CZ40 -> 0 | ED40: =(DR40*DS40)+(DU40*DV40)+(DX40*DY40)+(EA40*EB40) -> 0 | EE40: =ED40-DO40 -> 0
...

Sheet Feedback semanal
A1: FEEDBACK SEMANAL | B1: 1
A2: Ajuda-me a ajudar-te! Responde ás seguintes questões para que eu possa da melhor forma ajustar todas as variáveis para a próxima semana.
A3: · O que achaste da semana em geral (progressão/regressão)?
A6: · O que correu bem (dieta/treino/descanso)?
A9: · Que dificuldade sentiste (dieta/treino/descanso)?
A12: · Qual a tua perspectiva para a próxima semana?
A15: · Qual a tua motivação para a próxima semana (1-10)?
A16: FEEDBACK SEMANAL | B16: =1+B1 -> 2
A17: Ajuda-me a ajudar-te! Responde ás seguintes questões para que eu possa da melhor forma ajustar todas as variáveis para a próxima semana.
A18: · O que achaste da semana em geral (progressão/regressão)?
A21: · O que correu bem (dieta/treino/descanso)?
A24: · Que dificuldade sentiste (dieta/treino/descanso)?
A27: · Qual a tua perspectiva para a próxima semana?
A30: · Qual a tua motivação para a próxima semana (1-10)?
A31: FEEDBACK SEMANAL | B31: =1+B16 -> 3
A32: Ajuda-me a ajudar-te! Responde ás seguintes questões para que eu possa da melhor forma ajustar todas as variáveis para a próxima semana.
A33: · O que achaste da semana em geral (progressão/regressão)?
A36: · O que correu bem (dieta/treino/descanso)?
A39: · Que dificuldade sentiste (dieta/treino/descanso)?
A42: · Qual a tua perspectiva para a próxima semana?
A45: · Qual a tua motivação para a próxima semana (1-10)?
A46: FEEDBACK SEMANAL | B46: =1+B31 -> 4
A47: Ajuda-me a ajudar-te! Responde ás seguintes questões para que eu possa da melhor forma ajustar todas as variáveis para a próxima semana.
A48: · O que achaste da semana em geral (progressão/regressão)?
A51: · O que correu bem (dieta/treino/descanso)?
A54: · Que dificuldade sentiste (dieta/treino/descanso)?
A57: · Qual a tua perspectiva para a próxima semana?
A60: · Qual a tua motivação para a próxima semana (1-10)?
A61: FEEDBACK SEMANAL | B61: =1+B46 -> 5
A62: Ajuda-me a ajudar-te! Responde ás seguintes questões para que eu possa da melhor forma ajustar todas as variáveis para a próxima semana.
A63: · O que achaste da semana em geral (progressão/regressão)?
A66: · O que correu bem (dieta/treino/descanso)?
A69: · Que dificuldade sentiste (dieta/treino/descanso)?
A72: · Qual a tua perspectiva para a próxima semana?
A75: · Qual a tua motivação para a próxima semana (1-10)?
A76: FEEDBACK SEMANAL | B76: =1+B61 -> 6
A77: Ajuda-me a ajudar-te! Responde ás seguintes questões para que eu possa da melhor forma ajustar todas as variáveis para a próxima semana.
A78: · O que achaste da semana em geral (progressão/regressão)?
